Workbook

Sheet EVOLUTION BEURRE
B1: Motte | E1: Tourage
B2: Fuseau | C2: Back Europ | D2: Richard | E2: Fuseau | F2: Back Europ | G2: Richard
A3: 45576 | F3: 10.49
A4: 45572 | B4: 9.2 | E4: 11.13
A5: 45586 | B5: 8.3 | C5: 9.89 | D5: 8.82 | E5: 11.31 | F5: 10.49 | G5: 8.95
A6: 45583 | B6: 9.2
A7: 45565 | C7: 8.92 | F7: 9.28
A8: 45575 | C8: 9.89 | F8: 10.49 | G8: 8.95
A9: 45568 | G9: 9.899
A10: 45572 | D10: 8.924 | F10: 9.28

Sheet MERCURIALE -5%
A1: Ref interne | B1: Produits
A3: FRU15 | B3: Abricot 1/2 pelé sirop 5/1 | C3: 9.88 | D3: =+C3*0.94 -> 9.2872
A4: FRU16 | B4: Abricot Cube 5/5mms 4kg | C4: 8.34 | D4: =+C4*0.94 -> 7.8396
A5: FRU14 | B5: Abricot Sirop 3/1 | C5: 7.27 | D5: =+C5*0.94 -> 6.8338
A6: FRU13 | B6: Abricot sirop 5/1 | C6: 9.75 | D6: =+C6*0.94 -> 9.165
A7: PATISS37 | B7: Acide citrique poudre L.François 1kG | C7: 12.441 | D7: =+C7*0.94 -> 11.69454
A8: DIV082 | B8: Agent Démoulage Aerosol 500mL | C8: 2.75 | D8: =+C8*0.94 -> 2.585
A9: CHA18 | B9: Aiguillette poulet panée 1kG | C9: 7.24 | D9: =+C9*0.94 -> 6.8056
A10: CHA09 | B10: Aiguillettes P.Pané CORNFLAKES 1kG | C10: 7.8 | D10: =+C10*0.94 -> 7.332
A11: SNA19 | B11: Ail surgelé 4kg | C11: 18.5 | D11: =+C11*0.94 -> 17.39
A12: FRO17 | B12: Ail/fine herbe 500g | C12: 4.48 | D12: =+C12*0.94 -> 4.2112
A13: PATISS14 | B13: Amande entière 1kg | C13: 6.9 | D13: =+C13*0.94 -> 6.486
A14: PATISS12 | B14: Amande hachée 1kG | C14: 7.51 | D14: =+C14*0.94 -> 7.0594
... A16: FRU03 | B16: Amande poudre blanche 10kg | C16: 5.24 | D16: =+C16*0.94 -> 4.9256
B17: Amande poudre grise 10kg | C17: 5.31 | D17: =+C17*0.94 -> 4.9914
A18: PATISS11 | B18: Amandes effilée 5kG | C18: 5.15 | D18: =+C18*0.94 -> 4.841
A19: FRU17 | B19: Amandes emondées 1kG | C19: 6.89 | D19: =+C19*0.94 -> 6.4766
A20: PATISS15 | B20: Amandes poudre grise | C20: 5.31 | D20: =+C20*0.94 -> 4.9914
A21: FAR02 | B21: Améliorant Ibis Violet 10kg | C21: 6.83 | D21: =+C21*0.94 -> 6.4202
A22: PATISS28 | B22: Amidon Mais Seau 5kG | C22: 2.41 | D22: =+C22*0.94 -> 2.2654
A23: FRU19 | B23: Ananas Morceaux cube 1kG | C23: 4.77 | D23: =+C23*0.94 -> 4.4838
A24: PATISS73 | B24: Arome Café Brésilien 1L SEBALSE | C24: 17.9 | D24: =+C24*0.94 -> 16.826
B25: Arôme Chocolat
A26: PATISS74 | B26: Arome Vanille Boulpat 1L SEBALSE | C26: 8.79 | D26: =+C26*0.95 -> 8.3505
A27: DIV092 | B27: Assiette Sav ronde noire 88mns | C27: 0.08 | D27: =+C27*0.95 -> 0.076
A28: CHA10 | B28: Bacon tranche 1kG | C28: 10.6 | D28: =+C28*0.95 -> 10.07
A29: BOISS36 | B29: Badoit 33cL | D29: =+C29*0.95 -> 0
A30: LEG006 | B30: Banane | C30: 1.5 | D30: =+C30*0.95 -> 1.425
A31: PATISS22 | B31: Bâton chocolat 36cm 5kG | C31: 9.27 | D31: =+C31*0.95 -> 8.8065
A32: CREM19 | B32: Beurre 1/2 SEL VROUGE 80% 500g | C32: 4.63 | D32: =+C32*0.95 -> 4.3985
A33: CREM14 | B33: Beurre 82% Motte 10kG | C33: 8.3 | D33: =+C33*0.95 -> 7.885
A34: CREM15 | B34: Beurre 82% Motte 25kG | C34: 8.23 | D34: =+C34*0.95 -> 7.8185
A35: CREM16 | B35: Beurre Demi Sel 1kG | C35: 7.34 | D35: =+C35*0.95 -> 6.973
A36: CREM17 | B36: Beurre Tourage 10kG | C36: 9.1 | D36: =+C36*0.95 -> 8.645
A37: BOISS32 | B37: Bière Heineken 33cL | C37: 0.65 | D37: =+C37*0.95 -> 0.6175
A38: FRU25 | B38: Bigarreaux Sirop 4/4 | C38: 2.18 | D38: =+C38*0.95 -> 2.071
A39: OEU02 | B39: Blanc Œuf Liquide 1kG | C39: 3.51 | D39: =+C39*0.95 -> 3.3345
A40: FRO05 | B40: Bleu cube 1,3kg | C40: 13.19 | D40: =+C40*0.95 -> 12.5305
A41: DIV087 | B41: Bobine Papier 450 feuilles | C41: 2.53 | D41: =+C41*0.95 -> 2.4035
A42: DIV044 | B42: Boîte Burger | C42: 7.49 | D42: =+C42*0.95 -> 7.1155
...

Sheet SUIVI STOCKS LEBHAR
C1: Stock | D1: Conso N | E1: Conso N-1
A2: Boîtage | B2: Boîte 23*8 Gaufrage
B3: Boîte 18*8
B4: Boîte 20*8
B5: Boîte 23*8
B6: Boîte 26*8
B7: Boîte 29*8
A8: Sachets | B8: Taille 4
B9: Taille 6
B10: Taille 7
A11: Mousseline | B11: Mouss 20*30
B12: Mouss 30*40
B13: Mouss 40*60
A14: Baguette | B14: 100*60
B15: 140*60
B16: 260*75
B17: Sandwich Plastifié

Sheet TARIFS 12 2025
A1: Ref interne | B1: Produits | C1: Cond | D1: Fuseau | E1: BackEurop | F1: Team Ouest | G1: Autres | H1: Richard Distribution | I1: FOURNISSEUR SELEC | J1: TARIF
A3: FRU15 | B3: Abricot 1/2 pelé sirop 5/1 | C3: 1 | D3: 9.88 | I3: Fuseau | J3: 9.88
A4: FRU16 | B4: Abricot Cube 5/5mms 4kg | C4: 1 | D4: 8.34 | I4: Fuseau | J4: 8.34
A5: FRU14 | B5: Abricot Sirop 3/1 | C5: 1 | E5: 7.266 | H5: 5.855 | I5: Richard Distribution | J5: 5.855
A6: FRU13 | B6: Abricot sirop 5/1 | C6: 1 | D6: 9.88 | E6: 12.366 | H6: 9.75 | I6: Richard Distribution | J6: 9.75
A7: PATISS37 | B7: Acide citrique poudre L.François 1kG | C7: 1 | E7: 12.441 | I7: BackEurop THOMAS | J7: 12.441
A8: DIV082 | B8: Agent Démoulage Aerosol 500mL | C8: 1 | D8: 2.95 | E8: 2.961 | I8: Fuseau | J8: 2.75
A9: CHA18 | B9: Aiguillette poulet panée 1kG | C9: 1 | D9: 8.69 | E9: 7.55 | F9: 7.55 | I9: BackEurop THOMAS | J9: 7.24
A10: CHA09 | B10: Aiguillettes P.Pané CORNFLAKES 1kG | C10: 1 | D10: 7.8 | E10: 8.162 | F10: 8.1 | H10: 7.3 | I10: Richard Distribution | J10: 7.3
A11: SNA19 | B11: Ail surgelé 4kg | C11: 4 | D11: 18.5 | H11: =4.3*4 -> 17.2 | I11: Fuseau | J11: 17.2
A12: FRO17 | B12: Ail/fine herbe 500g | C12: 1 | D12: =8.95/2 -> 4.475 | E12: 5.134 | F12: 4.75 | I12: Fuseau | J12: 4.48
A13: PATISS14 | B13: Amande entière 1kg | C13: 1 | D13: 6.9 | E13: 7.32 | I13: Fuseau | J13: 6.9
A14: PATISS12 | B14: Amande hachée 1kG | C14: 1 | D14: 9.52 | E14: 7.509 | I14: BackEurop THOMAS | J14: 7.51
A15: PATISS13 | B15: Amande hachée 5kG | C15: 1 | E15: 9.805 | H15: 6.25 | I15: Richard Distribution | J15: 6.25
A16: FRU03 | B16: Amande poudre blanche 10kg | C16: 10 | D16: 5.24 | E16: 9.11 | I16: Fuseau | J16: 5.24
B17: Amande poudre grise 10kg | C17: 10 | D17: 5.307 | E17: 8.29 | I17: Fuseau | J17: 5.31
A18: PATISS11 | B18: Amandes effilée 5kG | C18: 1 | D18: 6.2 | E18: 9.805 | H18: 5.15 | I18: Richard Distribution | J18: 5.15
A19: FRU17 | B19: Amandes emondées 1kG | C19: 1 | D19: 6.89 | E19: 7.45 | I19: Fuseau | J19: 6.89
A20: PATISS15 | B20: Amandes poudre grise | C20: 10kg | D20: 5.31 | E20: 6.29 | I20: Fuseau | J20: 5.31
A21: FAR02 | B21: Améliorant Ibis Violet 10kg | C21: 1 | D21: 7.112 | E21: 6.83 | F21: 7.7 | I21: BackEurop THOMAS | J21: 6.83
A22: PATISS28 | B22: Amidon Mais Seau 5kG | C22: 1 | D22: 5.938 | E22: 2.407 | I22: BackEurop THOMAS | J22: 2.41
A23: FRU19 | B23: Ananas Morceaux cube 1kG | C23: 1 | E23: 4.766 | I23: BackEurop THOMAS | J23: 4.77
A24: PATISS73 | B24: Arome Café Brésilien 1L SEBALSE | C24: 1 | D24: 17.9 | E24: 20.86 | I24: Fuseau | J24: 17.9
B25: Arôme Chocolat | C25: 1 | G25: 11 | I25: ? | J25: =+G25 -> 11
A26: PATISS74 | B26: Arome Vanille Boulpat 1L SEBALSE | C26: 1 | D26: 13.86 | E26: 11.196 | H26: 8.2 | I26: Richard Distribution | J26: 8.2
A27: DIV092 | B27: Assiette Sav ronde noire 88mns | C27: 100 | D27: =7.5/100 -> 0.075 | E27: =6.58/50 -> 0.1316 | I27: Fuseau | J27: 0.08
A28: CHA10 | B28: Bacon tranche 1kG | C28: 1 | D28: 12.99 | E28: 14 | F28: =5.5*2 -> 11 | H28: 10.6 | I28: Richard Distribution | J28: 10.6
A29: BOISS36 | B29: Badoit 33cL | C29: 30 | I29: Fuseau
A30: LEG006 | B30: Banane | C30: 1 | G30: 1.5 | I30: Terre et marée | J30: 1.5
A31: PATISS22 | B31: Bâton chocolat 36cm 5kG | C31: 500 | D31: 10.9 | E31: 9.46 | H31: 8.25 | I31: Richard Distribution | J31: 8.25
A32: CREM19 | B32: Beurre 1/2 SEL VROUGE 80% 500g | C32: 1 | E32: 4.63 | I32: BackEurop THOMAS | J32: 4.63
A33: CREM14 | B33: Beurre 82% Motte 10kG | C33: 1 | E33: 10.09 | I33: BackEurop THOMAS | J33: 8.3
A34: CREM15 | B34: Beurre 82% Motte 25kG | C34: 1 | D34: 5.4 | E34: 5.38 | H34: 4.8 | I34: Richard Distribution | J34: 4.8
A35: CREM16 | B35: Beurre Demi Sel 1kG | C35: 1 | D35: 7.467 | E35: 7.34 | F35: 9.393 | I35: BackEurop THOMAS | J35: 7.34
A36: CREM17 | B36: Beurre Tourage 10kG | C36: 1 | D36: 9.5 | E36: 10.34 | H36: 9.1 | I36: TransGourmet | J36: 9.1
A37: BOISS32 | B37: Bière Heineken 33cL | C37: 24 | D37: 0.699 | H37: 0.694 | I37: Fuseau | J37: 0.65
A38: FRU25 | B38: Bigarreaux Sirop 4/4 | C38: 1 | E38: 2.182 | I38: BackEurop THOMAS | J38: 2.18
A39: OEU02 | B39: Blanc Œuf Liquide 1kG | C39: 1 | D39: 3.694 | E39: 3.506 | F39: 3.2 | H39: 3.29 | I39: Richard Distribution | J39: 3.29
A40: FRO05 | B40: Bleu cube 1,3kg | C40: 1 | D40: 16.17 | E40: 13.65 | F40: 13.69 | I40: BackEurop THOMAS | J40: 13.65
A41: DIV087 | B41: Bobine Papier 450 feuilles | C41: 450 | E41: 2.526 | I41: BackEurop THOMAS | J41: 2.53
...

Sheet VIENNOISERIE - PAP PARIS
A1: Coeff souhaité | B1: 4
A2: CROISSANT | E2: PAIN AU CHOCOLAT | I2: BRIOCHE | M2: BRIOCHE PEPITES
B3: Prix au kilo | C3: Quantité | F3: Prix au kilo | G3: Quantité | J3: Prix au kilo | K3: Quantité | N3: Prix au kilo | O3: Quantité
A4: Farine T45 | B4: =IFERROR(VLOOKUP(A4,'TARIFS 12 2025'!B3:J461,9,FALSE),"") -> 1.05 | C4: 2 | D4: =+C4*B4 -> 2.1 | E4: Farine T45 | F4: =IFERROR(VLOOKUP(E4,'TARIFS 12 2025'!B3:J466,9,FALSE),"") -> 1.05 | G4: 2 | H4: =+G4*F4 -> 2.1 | I4: Farine T45 | J4: =IFERROR(VLOOKUP(I4,'TARIFS 12 2025'!B3:J502,9,FALSE),"") -> 1.05 | K4: 1 | L4: =+K4*J4 -> 1.05 | M4: Farine T45 | N4: =IFERROR(VLOOKUP(M4,'TARIFS 12 2025'!B3:J510,9,FALSE),"") -> 1.05 | O4: 1 | P4: =+O4*N4 -> 1.05
A5: Sucre Crist Semoule 25kG | B5: =IFERROR(VLOOKUP(A5,'TARIFS 12 2025'!B4:J461,9,FALSE),"") -> 0.86 | C5: 0.22 | D5: =+C5*B5 -> 0.1892 | E5: Sucre Crist Semoule 25kG | F5: =IFERROR(VLOOKUP(E5,'TARIFS 12 2025'!B4:J469,9,FALSE),"") -> 0.86 | G5: 0.22 | H5: =+G5*F5 -> 0.1892 | I5: Sel fin 25kG | J5: =IFERROR(VLOOKUP(I5,'TARIFS 12 2025'!B4:J503,9,FALSE),"") -> 0.27 | K5: 0.02 | L5: =+K5*J5 -> 0.0054 | M5: Sel fin 25kG | N5: =IFERROR(VLOOKUP(M5,'TARIFS 12 2025'!B4:J511,9,FALSE),"") -> 0.27 | O5: 0.02 | P5: =+O5*N5 -> 0.0054
A6: Sel fin 25kG | B6: =IFERROR(VLOOKUP(A6,'TARIFS 12 2025'!B5:J462,9,FALSE),"") -> 0.27 | C6: 0.04 | D6: =+C6*B6 -> 0.0108 | E6: Sel fin 25kG | F6: =IFERROR(VLOOKUP(E6,'TARIFS 12 2025'!B5:J470,9,FALSE),"") -> 0.27 | G6: 0.04 | H6: =+G6*F6 -> 0.0108 | I6: Levure Hirondelle 1895 Bande 2,5kG | J6: =IFERROR(VLOOKUP(I6,'TARIFS 12 2025'!B5:J504,9,FALSE),"") -> 3.45 | K6: 0.04 | L6: =+K6*J6 -> 0.138 | M6: Levure Hirondelle 1895 Bande 2,5kG | N6: =IFERROR(VLOOKUP(M6,'TARIFS 12 2025'!B5:J512,9,FALSE),"") -> 3.45 | O6: 0.04 | P6: =+O6*N6 -> 0.138
A7: Top Fournil | B7: =IFERROR(VLOOKUP(A7,'TARIFS 12 2025'!B6:J463,9,FALSE),"") | C7: 0.016 | D7: =4.49*C7 -> 0.07184 | E7: Top Fournil | F7: =IFERROR(VLOOKUP(E7,'TARIFS 12 2025'!B6:J471,9,FALSE),"") -> 4.49 | G7: 0.016 | H7: =+G7*F7 -> 0.07184 | I7: Miel Seau 5kg | J7: =IFERROR(VLOOKUP(I7,'TARIFS 12 2025'!B6:J505,9,FALSE),"") -> 3.99 | K7: 0.08 | L7: =+K7*J7 -> 0.3192 | M7: Miel Seau 5kg | N7: =IFERROR(VLOOKUP(M7,'TARIFS 12 2025'!B6:J513,9,FALSE),"") -> 3.99 | O7: 0.08 | P7: =+O7*N7 -> 0.3192
A8: Levure Hirondelle 1895 Bande 2,5kG | B8: =IFERROR(VLOOKUP(A8,'TARIFS 12 2025'!B7:J463,9,FALSE),"") -> 3.45 | C8: 0.08 | D8: =+C8*B8 -> 0.276 | E8: Levure Hirondelle 1895 Bande 2,5kG | F8: =IFERROR(VLOOKUP(E8,'TARIFS 12 2025'!B7:J472,9,FALSE),"") -> 3.45 | G8: 0.08 | H8: =+G8*F8 -> 0.276 | I8: Œuf Frais | J8: =IFERROR(VLOOKUP(I8,'TARIFS 12 2025'!B7:J506,9,FALSE),"") -> 2.72 | K8: 0.4 | L8: =+K8*J8 -> 1.088 | M8: Œuf Frais | N8: =IFERROR(VLOOKUP(M8,'TARIFS 12 2025'!B7:J514,9,FALSE),"") -> 2.72 | O8: 0.4 | P8: =+O8*N8 -> 1.088
A9: Beurre Tourage 10kG | B9: 9.5 | C9: 1 | D9: =+C9*B9 -> 9.5 | E9: Beurre Tourage 10kG | F9: 9.5 | G9: 1 | H9: =+G9*F9 -> 9.5 | I9: Top Fournil | J9: =IFERROR(VLOOKUP(I9,'TARIFS 12 2025'!B8:J507,9,FALSE),"") -> 4.49 | K9: 0.05 | L9: =+K9*J9 -> 0.2245 | M9: Top Fournil | N9: =IFERROR(VLOOKUP(M9,'TARIFS 12 2025'!B8:J515,9,FALSE),"") -> 4.49 | O9: 0.05 | P9: =+O9*N9 -> 0.2245
A10: Beurre 82% Motte 25kG | B10: =IFERROR(VLOOKUP(A10,'TARIFS 12 2025'!B9:J465,9,FALSE),"") -> 4.8 | C10: 0.16 | D10: =+C10*B10 -> 0.768 | E10: Beurre 82% Motte 25kG | F10: =IFERROR(VLOOKUP(E10,'TARIFS 12 2025'!B9:J474,9,FALSE),"") -> 4.8 | G10: 0.16 | H10: =+G10*F10 -> 0.768 | I10: Pâte Fermenté | J10: =IFERROR(VLOOKUP(I10,'TARIFS 12 2025'!B9:J508,9,FALSE),"") -> 0.47273529 | K10: 0.3 | L10: =+K10*J10 -> 0.14182059 | M10: Pâte Fermenté | N10: =IFERROR(VLOOKUP(M10,'TARIFS 12 2025'!B9:J516,9,FALSE),"") -> 0.47273529 | O10: 0.3 | P10: =+O10*N10 -> 0.14182059
A11: Eau | B11: =IFERROR(VLOOKUP(A11,'TARIFS 12 2025'!B10:J466,9,FALSE),"") -> 0.004 | C11: 0.8 | D11: =+C11*B11 -> 0.0032 | E11: Eau | F11: =IFERROR(VLOOKUP(E11,'TARIFS 12 2025'!B10:J475,9,FALSE),"") -> 0.004 | G11: 0.8 | H11: =+G11*F11 -> 0.0032 | I11: Sucre Crist Semoule 25kG | J11: =IFERROR(VLOOKUP(I11,'TARIFS 12 2025'!B10:J509,9,FALSE),"") -> 0.86 | K11: 0.2 | L11: =+K11*J11 -> 0.172 | M11: Sucre Crist Semoule 25kG | N11: =IFERROR(VLOOKUP(M11,'TARIFS 12 2025'!B10:J517,9,FALSE),"") -> 0.86 | O11: 0.2 | P11: =+O11*N11 -> 0.172
A12: Miel Seau 5kg | B12: =IFERROR(VLOOKUP(A12,'TARIFS 12 2025'!B11:J469,9,FALSE),"") -> 3.99 | C12: 0.06 | D12: =+C12*B12 -> 0.2394 | E12: Miel Seau 5kg | F12: =IFERROR(VLOOKUP(E12,'TARIFS 12 2025'!B11:J476,9,FALSE),"") -> 3.99 | G12: 0.06 | H12: =+G12*F12 -> 0.2394 | I12: Beurre 82% Motte 25kG | J12: =IFERROR(VLOOKUP(I12,'TARIFS 12 2025'!B11:J510,9,FALSE),"") -> 4.8 | K12: 0.35 | L12: =+K12*J12 -> 1.68 | M12: Beurre 82% Motte 25kG | N12: =IFERROR(VLOOKUP(M12,'TARIFS 12 2025'!B11:J518,9,FALSE),"") -> 4.8 | O12: 0.35 | P12: =+O12*N12 -> 1.68
A13: Pâte Fermenté | B13: =IFERROR(VLOOKUP(A13,'TARIFS 12 2025'!B12:J470,9,FALSE),"") -> 0.47273529 | C13: 0.5 | D13: =+C13*B13 -> 0.23636765 | E13: Pâte Fermenté | F13: =IFERROR(VLOOKUP(E13,'TARIFS 12 2025'!B12:J477,9,FALSE),"") -> 0.47273529 | G13: 0.5 | H13: =+G13*F13 -> 0.23636765 | I13: Eau | J13: =IFERROR(VLOOKUP(I13,'TARIFS 12 2025'!B12:J511,9,FALSE),"") -> 0.004 | K13: 0.1 | L13: =+K13*J13 -> 0.0004 | M13: Eau | N13: =IFERROR(VLOOKUP(M13,'TARIFS 12 2025'!B12:J519,9,FALSE),"") -> 0.004 | O13: 0.1 | P13: =+O13*N13 -> 0.0004
A14: Œuf Frais | B14: =IFERROR(VLOOKUP(A14,'TARIFS 12 2025'!B13:J471,9,FALSE),"") -> 2.72 | C14: 0.12 | D14: =+C14*B14 -> 0.3264 | E14: Œuf Frais | F14: =IFERROR(VLOOKUP(E14,'TARIFS 12 2025'!B13:J478,9,FALSE),"") -> 2.72 | G14: 0.12 | H14: =+G14*F14 -> 0.3264 | M14: Drops chocolat 44% 25kG | N14: =IFERROR(VLOOKUP(M14,'TARIFS 12 2025'!B13:J520,9,FALSE),"") -> 5.95 | O14: 0.06 | P14: =+O14*N14 -> 0.357
C15: =SUM(C4:C14) -> 4.996 | E15: Bâton chocolat 36cm 5kG | F15: =IFERROR(VLOOKUP(E15,'TARIFS 12 2025'!B14:J480,9,FALSE),"") -> 8.25 | G15: 0.488 | H15: =+G15*F15 -> 4.026 | J15: =IFERROR(VLOOKUP(I15,'TARIFS 12 2025'!B14:J513,9,FALSE),"")
G16: =SUM(G4:G15) -> 5.484 | K16: =SUM(K4:K13) -> 2.54 | O16: =SUM(O4:O14) -> 2.6
C17: pour 62 | D17: =+SUM(D4:D15) -> 13.721208 | G17: pour un paton | H17: =+SUM(H4:H15) -> 17.747208 | K17: pour 4 | L17: =+SUM(L4:L15) -> 4.8193206 | O17: pour 4,73 | P17: =SUM(P4:P15) -> 5.1763206
C18: pour 1 | D18: =0.068*D17/C15 -> 0.18675783 | G18: pour 1 | H18: =0.068*H17/G16 -> 0.2200602 | K18: pour 1 | L18: =0.6*L17/K16+0.14 -> 1.2784222 | O18: pour 1 | P18: =0.6*P17/O16 -> 1.1945355
C19: Vendu TTC | D19: 1.2 | G19: Vendu TTC | H19: 1.25 | K19: Vendu TTC | L19: 7.2 | O19: Vendu TTC | P19: 7.4
C20: Vendu HT | D20: =D19/(1+5.5/100) -> 1.1374408 | G20: Vendu HT | H20: =H19/(1+5.5/100) -> 1.1848341 | K20: Vendu HT | L20: =L19/(1+5.5/100) -> 6.8246445 | O20: Vendu HT | P20: =P19/(1+5.5/100) -> 7.014218
C21: Coef | D21: =+D20/D18 -> 6.0904582 | G21: Coef | H21: =+H20/H18 -> 5.3841364 | K21: Coef | L21: =+L20/L18 -> 5.3383339 | O21: Coef | P21: =+P20/P18 -> 5.8719208
C22: Marge | D22: =(D20-D18)*100/D20 -> 83.580874 | G22: Marge | H22: =(H20-H18)*100/H20 -> 81.426919 | K22: Marge | L22: =(L20-L18)*100/L20 -> 81.267564 | O22: Marge | P22: =(P20-P18)*100/P20 -> 82.969798
A24: BRIOCHETTE | E24: GRANDE VIENNOISE | I24: VIENNOISE PEPITE | M24: VIENNOISE NATURE
B25: Prix au kilo | C25: Quantité | F25: Prix au kilo | G25: Quantité | J25: Prix au kilo | K25: Quantité | N25: Prix au kilo | O25: Quantité
A26: Farine T45 | B26: =IFERROR(VLOOKUP(A26,'TARIFS 12 2025'!B3:J525,9,FALSE),"") -> 1.05 | C26: 1 | D26: =+C26*B26 -> 1.05 | E26: Farine T45 | F26: =IFERROR(VLOOKUP(E26,'TARIFS 12 2025'!B3:J493,9,FALSE),"") -> 1.05 | G26: 6 | H26: =+G26*F26 -> 6.3 | I26: Farine T45 | J26: =IFERROR(VLOOKUP(I26,'TARIFS 12 2025'!B3:J491,9,FALSE),"") -> 1.05 | K26: 6 | L26: =+K26*J26 -> 6.3 | M26: Farine T45 | N26: =IFERROR(VLOOKUP(M26,'TARIFS 12 2025'!B3:J501,9,FALSE),"") -> 1.05 | O26: 6 | P26: =+O26*N26 -> 6.3
A27: Sel fin 25kG | B27: =IFERROR(VLOOKUP(A27,'TARIFS 12 2025'!B4:J526,9,FALSE),"") -> 0.27 | C27: 0.02 | D27: =+C27*B27 -> 0.0054 | E27: Sel fin 25kG | F27: =IFERROR(VLOOKUP(E27,'TARIFS 12 2025'!B4:J494,9,FALSE),"") -> 0.27 | G27: 0.12 | H27: =+G27*F27 -> 0.0324 | I27: Sel fin 25kG | J27: =IFERROR(VLOOKUP(I27,'TARIFS 12 2025'!B4:J492,9,FALSE),"") -> 0.27 | K27: 0.12 | L27: =+K27*J27 -> 0.0324 | M27: Sel fin 25kG | N27: =IFERROR(VLOOKUP(M27,'TARIFS 12 2025'!B4:J502,9,FALSE),"") -> 0.27 | O27: 0.12 | P27: =+O27*N27 -> 0.0324
A28: Levure Hirondelle 1895 Bande 2,5kG | B28: =IFERROR(VLOOKUP(A28,'TARIFS 12 2025'!B5:J527,9,FALSE),"") -> 3.45 | C28: 0.04 | D28: =+C28*B28 -> 0.138 | E28: Levure Hirondelle 1895 Bande 2,5kG | F28: =IFERROR(VLOOKUP(E28,'TARIFS 12 2025'!B5:J495,9,FALSE),"") -> 3.45 | G28: 0.25 | H28: =+G28*F28 -> 0.8625 | I28: Levure Hirondelle 1895 Bande 2,5kG | J28: =IFERROR(VLOOKUP(I28,'TARIFS 12 2025'!B5:J493,9,FALSE),"") -> 3.45 | K28: 0.25 | L28: =+K28*J28 -> 0.8625 | M28: Levure Hirondelle 1895 Bande 2,5kG | N28: =IFERROR(VLOOKUP(M28,'TARIFS 12 2025'!B5:J503,9,FALSE),"") -> 3.45 | O28: 0.25 | P28: =+O28*N28 -> 0.8625
A29: Miel Seau 5kg | B29: =IFERROR(VLOOKUP(A29,'TARIFS 12 2025'!B6:J528,9,FALSE),"") -> 3.99 | C29: 0.08 | D29: =+C29*B29 -> 0.3192 | E29: Poudre lait Entier 26% 25kG | F29: =IFERROR(VLOOKUP(E29,'TARIFS 12 2025'!B6:J496,9,FALSE),"") -> 5.16 | G29: 0.3 | H29: =+G29*F29 -> 1.548 | I29: Poudre lait Entier 26% 25kG | J29: =IFERROR(VLOOKUP(I29,'TARIFS 12 2025'!B6:J494,9,FALSE),"") -> 5.16 | K29: 0.3 | L29: =+K29*J29 -> 1.548 | M29: Poudre lait Entier 26% 25kG | N29: =IFERROR(VLOOKUP(M29,'TARIFS 12 2025'!B6:J504,9,FALSE),"") -> 5.16 | O29: 0.3 | P29: =+O29*N29 -> 1.548
A30: Œuf Frais | B30: =IFERROR(VLOOKUP(A30,'TARIFS 12 2025'!B7:J529,9,FALSE),"") -> 2.72 | C30: 7 | D30: =+C30*B30 -> 19.04 | E30: Eau | F30: =IFERROR(VLOOKUP(E30,'TARIFS 12 2025'!B7:J497,9,FALSE),"") -> 0.004 | G30: 2.2 | H30: =+G30*F30 -> 0.0088 | I30: Eau | J30: =IFERROR(VLOOKUP(I30,'TARIFS 12 2025'!B7:J495,9,FALSE),"") -> 0.004 | K30: 2.2 | L30: =+K30*J30 -> 0.0088 | M30: Eau | N30: =IFERROR(VLOOKUP(M30,'TARIFS 12 2025'!B7:J505,9,FALSE),"") -> 0.004 | O30: 2.2 | P30: =+O30*N30 -> 0.0088
A31: Top Fournil | B31: =IFERROR(VLOOKUP(A31,'TARIFS 12 2025'!B8:J530,9,FALSE),"") -> 4.49 | C31: 0.05 | D31: =+C31*B31 -> 0.2245 | E31: Œuf Frais | F31: =IFERROR(VLOOKUP(E31,'TARIFS 12 2025'!B8:J498,9,FALSE),"") -> 2.72 | G31: 13 | H31: =+G31*F31 -> 35.36 | I31: Œuf Frais | J31: =IFERROR(VLOOKUP(I31,'TARIFS 12 2025'!B8:J496,9,FALSE),"") -> 2.72 | K31: 13 | L31: =+K31*J31 -> 35.36 | M31: Œuf Frais | N31: =IFERROR(VLOOKUP(M31,'TARIFS 12 2025'!B8:J506,9,FALSE),"") -> 2.72 | O31: 0.72 | P31: =+O31*N31 -> 1.9584
A32: Pâte Fermenté | B32: =IFERROR(VLOOKUP(A32,'TARIFS 12 2025'!B9:J531,9,FALSE),"") -> 0.47273529 | C32: 0.3 | D32: =+C32*B32 -> 0.14182059 | E32: Top Fournil | F32: =IFERROR(VLOOKUP(E32,'TARIFS 12 2025'!B9:J499,9,FALSE),"") -> 4.49 | G32: 0.03 | H32: =+G32*F32 -> 0.1347 | I32: Top Fournil | J32: =IFERROR(VLOOKUP(I32,'TARIFS 12 2025'!B9:J497,9,FALSE),"") -> 4.49 | K32: 0.03 | L32: =+K32*J32 -> 0.1347 | M32: Top Fournil | N32: =IFERROR(VLOOKUP(M32,'TARIFS 12 2025'!B9:J507,9,FALSE),"") -> 4.49 | O32: 0.03 | P32: =+O32*N32 -> 0.1347
A33: Sucre Crist Semoule 25kG | B33: =IFERROR(VLOOKUP(A33,'TARIFS 12 2025'!B10:J532,9,FALSE),"") -> 0.86 | C33: 0.2 | D33: =+C33*B33 -> 0.172 | E33: Sucre Crist Semoule 25kG | F33: =IFERROR(VLOOKUP(E33,'TARIFS 12 2025'!B10:J500,9,FALSE),"") -> 0.86 | G33: 0.36 | H33: =+G33*F33 -> 0.3096 | I33: Sucre Crist Semoule 25kG | J33: =IFERROR(VLOOKUP(I33,'TARIFS 12 2025'!B10:J498,9,FALSE),"") -> 0.86 | K33: 0.36 | L33: =+K33*J33 -> 0.3096 | M33: Sucre Crist Semoule 25kG | N33: =IFERROR(VLOOKUP(M33,'TARIFS 12 2025'!B10:J508,9,FALSE),"") -> 0.86 | O33: 0.36 | P33: =+O33*N33 -> 0.3096
A34: Beurre 82% Motte 25kG | B34: =IFERROR(VLOOKUP(A34,'TARIFS 12 2025'!B11:J533,9,FALSE),"") -> 4.8 | C34: 0.35 | D34: =+C34*B34 -> 1.68 | E34: Beurre 82% Motte 25kG | F34: =IFERROR(VLOOKUP(E34,'TARIFS 12 2025'!B11:J501,9,FALSE),"") -> 4.8 | G34: 1.2 | H34: =+G34*F34 -> 5.76 | I34: Beurre 82% Motte 25kG | J34: =IFERROR(VLOOKUP(I34,'TARIFS 12 2025'!B11:J499,9,FALSE),"") -> 4.8 | K34: 1.2 | L34: =+K34*J34 -> 5.76 | M34: Beurre 82% Motte 25kG | N34: =IFERROR(VLOOKUP(M34,'TARIFS 12 2025'!B11:J509,9,FALSE),"") -> 4.8 | O34: 1.2 | P34: =+O34*N34 -> 5.76
A35: Eau | B35: =IFERROR(VLOOKUP(A35,'TARIFS 12 2025'!B12:J534,9,FALSE),"") -> 0.004 | C35: 0.1 | D35: =+C35*B35 -> 0.0004 | I35: Drops chocolat 44% 25kG | J35: =IFERROR(VLOOKUP(I35,'TARIFS 12 2025'!B12:J500,9,FALSE),"") -> 5.95 | K35: 0.01 | L35: =+K35*J35 -> 0.0595
F36: =IFERROR(VLOOKUP(E36,'TARIFS 12 2025'!B13:J503,9,FALSE),"") | J36: =IFERROR(VLOOKUP(I36,'TARIFS 12 2025'!F13:N503,9,FALSE),"") | N36: =IFERROR(VLOOKUP(M36,'TARIFS 12 2025'!J13:R503,9,FALSE),"")
F37: =IFERROR(VLOOKUP(E37,'TARIFS 12 2025'!B14:J504,9,FALSE),"") | J37: =IFERROR(VLOOKUP(I37,'TARIFS 12 2025'!F14:N504,9,FALSE),"") | N37: =IFERROR(VLOOKUP(M37,'TARIFS 12 2025'!J14:R504,9,FALSE),"")
O38: =SUM(O26:O34) -> 11.18
C39: pour 25 | D39: =+SUM(D26:D37) -> 22.771321 | G39: pour 44,72 | H39: =+SUM(H26:H37) -> 50.316 | K39: pour 56 | L39: =+SUM(L26:L37) -> 50.3755 | O39: pour 112 | P39: =+SUM(P26:P37) -> 16.9144
C40: pour 1 | D40: =+D39/25 -> 0.91085282 | G40: pour 1 | H40: =+H39/44.72 -> 1.1251342 | K40: pour 1 | L40: =+L39/56 -> 0.8995625 | O40: pour 1 | P40: =0.1*P39/O38 -> 0.15129159
C41: Vendu TTC | D41: 1.8 | G41: Vendu TTC | H41: 1.8 | K41: Vendu TTC | L41: 1.1 | O41: Vendu TTC | P41: 1
...

Sheet REVENTE - PAP PARIS
A1: Coeff souhaité | B1: 4
A2: PAIN BURGER | E2: PAIN DE MIE | I2: SABLEE FOURREE | M2: GALETTE CHARENTAISE
B3: Prix au kilo | C3: Quantité | F3: Prix au kilo | G3: Quantité | J3: Prix au kilo | K3: Quantité | N3: Prix au kilo | O3: Quantité
A4: Farine T45 | B4: =IFERROR(VLOOKUP(A4,'TARIFS 12 2025'!B3:J461,9,FALSE),"") -> 1.05 | C4: 2.35 | D4: =+C4*B4 -> 2.4675 | E4: Farine T45 | F4: =IFERROR(VLOOKUP(E4,'TARIFS 12 2025'!B3:J466,9,FALSE),"") -> 1.05 | G4: 9 | H4: =+G4*F4 -> 9.45 | I4: Beurre 82% Motte 25kG | J4: =IFERROR(VLOOKUP(I4,'TARIFS 12 2025'!B3:J502,9,FALSE),"") -> 4.8 | K4: 4 | L4: =+K4*J4 -> 19.2 | M4: Beurre 82% Motte 25kG | N4: =IFERROR(VLOOKUP(M4,'TARIFS 12 2025'!B3:J510,9,FALSE),"") -> 4.8 | O4: 1 | P4: =+O4*N4 -> 4.8
A5: Eau | B5: =IFERROR(VLOOKUP(A5,'TARIFS 12 2025'!B4:J461,9,FALSE),"") -> 0.004 | C5: 1.05 | D5: =+C5*B5 -> 0.0042 | E5: Eau | F5: =IFERROR(VLOOKUP(E5,'TARIFS 12 2025'!B4:J469,9,FALSE),"") -> 0.004 | G5: 4 | H5: =+G5*F5 -> 0.016 | I5: Sucre Crist Semoule 25kG | J5: =IFERROR(VLOOKUP(I5,'TARIFS 12 2025'!B4:J503,9,FALSE),"") -> 0.86 | K5: 4 | L5: =+K5*J5 -> 3.44 | M5: Sucre Crist Semoule 25kG | N5: =IFERROR(VLOOKUP(M5,'TARIFS 12 2025'!B4:J511,9,FALSE),"") -> 0.86 | O5: 2.5 | P5: =+O5*N5 -> 2.15
A6: Poudre lait Entier 26% 25kG | B6: =IFERROR(VLOOKUP(A6,'TARIFS 12 2025'!B5:J462,9,FALSE),"") -> 5.16 | C6: 0.12 | D6: =+C6*B6 -> 0.6192 | E6: Sel fin 25kG | F6: =IFERROR(VLOOKUP(E6,'TARIFS 12 2025'!B5:J470,9,FALSE),"") -> 0.27 | G6: 0.18 | H6: =+G6*F6 -> 0.0486 | I6: Œuf Frais | J6: =IFERROR(VLOOKUP(I6,'TARIFS 12 2025'!B5:J504,9,FALSE),"") -> 2.72 | K6: 30 | L6: =+K6*J6 -> 81.6 | M6: Œuf Frais | N6: =IFERROR(VLOOKUP(M6,'TARIFS 12 2025'!B5:J512,9,FALSE),"") -> 2.72 | O6: =15*0.055 -> 0.825 | P6: =+O6*N6 -> 2.244
A7: Sel fin 25kG | B7: =IFERROR(VLOOKUP(A7,'TARIFS 12 2025'!B6:J463,9,FALSE),"") -> 0.27 | C7: 0.035 | D7: =+C7*B7 -> 0.00945 | E7: Levure Hirondelle 1895 Bande 2,5kG | F7: =IFERROR(VLOOKUP(E7,'TARIFS 12 2025'!B6:J471,9,FALSE),"") -> 3.45 | G7: 0.35 | H7: =+G7*F7 -> 1.2075 | I7: Levure chimique 1kG | J7: =IFERROR(VLOOKUP(I7,'TARIFS 12 2025'!B6:J505,9,FALSE),"") -> 4.69 | K7: 0.16 | L7: =+K7*J7 -> 0.7504 | M7: Levure chimique 1kG | N7: =IFERROR(VLOOKUP(M7,'TARIFS 12 2025'!B6:J513,9,FALSE),"") -> 4.69 | O7: 0.08 | P7: =+O7*N7 -> 0.3752
A8: Levure Hirondelle 1895 Bande 2,5kG | B8: =IFERROR(VLOOKUP(A8,'TARIFS 12 2025'!B7:J463,9,FALSE),"") -> 3.45 | C8: 0.07 | D8: =+C8*B8 -> 0.2415 | E8: Sucre Crist Semoule 25kG | F8: =IFERROR(VLOOKUP(E8,'TARIFS 12 2025'!B7:J472,9,FALSE),"") -> 0.86 | G8: 0.8 | H8: =+G8*F8 -> 0.688 | I8: Farine T45 | J8: =IFERROR(VLOOKUP(I8,'TARIFS 12 2025'!B7:J506,9,FALSE),"") -> 1.05 | K8: 8 | L8: =+K8*J8 -> 8.4 | M8: Farine T45 | N8: =IFERROR(VLOOKUP(M8,'TARIFS 12 2025'!B7:J514,9,FALSE),"") -> 1.05 | O8: 4 | P8: =+O8*N8 -> 4.2
A9: Sucre Crist Semoule 25kG | B9: =IFERROR(VLOOKUP(A9,'TARIFS 12 2025'!B8:J464,9,FALSE),"") -> 0.86 | C9: 0.18 | D9: =+C9*B9 -> 0.1548 | E9: Beurre 82% Motte 25kG | F9: =IFERROR(VLOOKUP(E9,'TARIFS 12 2025'!B8:J473,9,FALSE),"") -> 4.8 | G9: 1 | H9: =+G9*F9 -> 4.8 | I9: Sel fin 25kG | J9: =IFERROR(VLOOKUP(I9,'TARIFS 12 2025'!B8:J507,9,FALSE),"") -> 0.27 | K9: 0.08 | L9: =+K9*J9 -> 0.0216 | M9: Sel fin 25kG | N9: =IFERROR(VLOOKUP(M9,'TARIFS 12 2025'!B8:J515,9,FALSE),"") -> 0.27 | O9: 0.04 | P9: =+O9*N9 -> 0.0108
A10: Huile de tournesol 5L | B10: =IFERROR(VLOOKUP(A10,'TARIFS 12 2025'!B9:J465,9,FALSE),"") -> 1.8 | C10: 0.35 | D10: =+C10*B10 -> 0.63 | E10: Vinaigre de cidre 1l | F10: 2.19 | G10: 0.35 | H10: =+G10*F10 -> 0.7665 | J10: =IFERROR(VLOOKUP(I10,'TARIFS 12 2025'!B9:J508,9,FALSE),"") | M10: Margarine 10kg | N10: =IFERROR(VLOOKUP(M10,'TARIFS 12 2025'!B9:J516,9,FALSE),"") -> 2.5 | O10: 1 | P10: =+O10*N10 -> 2.5
A11: Œuf Frais | B11: =IFERROR(VLOOKUP(A11,'TARIFS 12 2025'!B10:J466,9,FALSE),"") -> 2.72 | C11: 0.22 | D11: =+C11*B11 -> 0.5984 | F11: =IFERROR(VLOOKUP(E11,'TARIFS 12 2025'!B10:J475,9,FALSE),"") | J11: =IFERROR(VLOOKUP(I11,'TARIFS 12 2025'!B10:J509,9,FALSE),"") | N11: =IFERROR(VLOOKUP(M11,'TARIFS 12 2025'!B10:J517,9,FALSE),"")
B12: =IFERROR(VLOOKUP(A12,'TARIFS 12 2025'!B11:J469,9,FALSE),"") | F12: =IFERROR(VLOOKUP(E12,'TARIFS 12 2025'!B11:J476,9,FALSE),"") | J12: =IFERROR(VLOOKUP(I12,'TARIFS 12 2025'!B11:J510,9,FALSE),"") | N12: =IFERROR(VLOOKUP(M12,'TARIFS 12 2025'!B11:J518,9,FALSE),"")
B13: =IFERROR(VLOOKUP(A13,'TARIFS 12 2025'!B12:J470,9,FALSE),"") | F13: =IFERROR(VLOOKUP(E13,'TARIFS 12 2025'!B12:J477,9,FALSE),"") | J13: =IFERROR(VLOOKUP(I13,'TARIFS 12 2025'!B12:J511,9,FALSE),"") | N13: =IFERROR(VLOOKUP(M13,'TARIFS 12 2025'!B12:J519,9,FALSE),"")
B14: =IFERROR(VLOOKUP(A14,'TARIFS 12 2025'!B13:J471,9,FALSE),"") | F14: =IFERROR(VLOOKUP(E14,'TARIFS 12 2025'!B13:J478,9,FALSE),"") | J14: =IFERROR(VLOOKUP(I14,'TARIFS 12 2025'!B13:J512,9,FALSE),"") | N14: =IFERROR(VLOOKUP(M14,'TARIFS 12 2025'!B13:J520,9,FALSE),"")
F15: =IFERROR(VLOOKUP(E15,'TARIFS 12 2025'!B14:J479,9,FALSE),"") | J15: =IFERROR(VLOOKUP(I15,'TARIFS 12 2025'!B14:J513,9,FALSE),"") | N15: =IFERROR(VLOOKUP(M15,'TARIFS 12 2025'!B14:J521,9,FALSE),"")
F16: =IFERROR(VLOOKUP(E16,'TARIFS 12 2025'!B15:J480,9,FALSE),"")
C17: pour 40 | D17: =+SUM(D4:D15) -> 4.72505 | F17: =IFERROR(VLOOKUP(E17,'TARIFS 12 2025'!B16:J481,9,FALSE),"") | G17: pour 31,36 | H17: =+SUM(H4:H15) -> 16.9766 | K17: pour 4 | L17: =+SUM(L4:L15) -> 113.412 | O17: pour 9,44 | P17: =+SUM(P4:P15) -> 16.28
C18: pour 1 | D18: =+D17/40 -> 0.11812625 | F18: =IFERROR(VLOOKUP(E18,'TARIFS 12 2025'!B17:J482,9,FALSE),"") | G18: pour 1 | H18: =+H17/31.36 -> 0.54134566 | K18: pour 1 | L18: =+L17/4 -> 28.353 | O18: pour 1 | P18: =+P17/9.44*0.45 -> 0.77605932
C19: Mini | D19: =D18/5 -> 0.02362525 | F19: =IFERROR(VLOOKUP(E19,'TARIFS 12 2025'!B18:J483,9,FALSE),"") | I19: 17890 | M19: 9445 | P19: =0.05*P18/1 -> 0.038802966
C20: Vendu HT | D20: 0.85 | F20: =IFERROR(VLOOKUP(E20,'TARIFS 12 2025'!B19:J484,9,FALSE),"") | G20: Vendu HT | H20: 4.25 | K20: Vendu HT | L20: 6.52 | O20: Vendu HT | P20: 0.6615
C21: Coef | D21: =+D20/D18 -> 7.1956911 | F21: =IFERROR(VLOOKUP(E21,'TARIFS 12 2025'!B20:J485,9,FALSE),"") | G21: Coef | H21: =+H20/H18 -> 7.8508064 | K21: Coef | L21: =+L20/L18 -> 0.22995803 | O21: Coef | P21: =+P20/P18 -> 0.85238329
F22: =IFERROR(VLOOKUP(E22,'TARIFS 12 2025'!B21:J486,9,FALSE),"")
F23: =IFERROR(VLOOKUP(E23,'TARIFS 12 2025'!B22:J487,9,FALSE),"")
A24: COOKIE | E24: COOKIE PISTACHE | I24: CHOUQUETTE | M24: BOTTEREAUX
B25: Prix au kilo | C25: Quantité | F25: =IFERROR(VLOOKUP(E25,'TARIFS 12 2025'!B24:J489,9,FALSE),"") | G25: Quantité | J25: Prix au kilo | K25: Quantité | N25: Prix au kilo | O25: Quantité
A26: Beurre 82% Motte 25kG | B26: =IFERROR(VLOOKUP(A26,'TARIFS 12 2025'!B3:J525,9,FALSE),"") -> 4.8 | C26: 0.9375 | D26: =+C26*B26 -> 4.5 | E26: Pâte à cookie | F26: =IFERROR(VLOOKUP(E26,'TARIFS 12 2025'!B25:J490,9,FALSE),"") -> 1.91 | G26: 10.625 | H26: =+G26*F26 -> 20.29375 | I26: Eau | J26: =IFERROR(VLOOKUP(I26,'TARIFS 12 2025'!B3:J491,9,FALSE),"") -> 0.004 | K26: 5 | L26: =+K26*J26 -> 0.02 | M26: Farine Emilie TF T65 | N26: =IFERROR(VLOOKUP(M26,'TARIFS 12 2025'!B3:J501,9,FALSE),"") -> 0.705 | O26: 50 | P26: =+O26*N26 -> 35.25
A27: Margarine 10kg | B27: =IFERROR(VLOOKUP(A27,'TARIFS 12 2025'!B4:J526,9,FALSE),"") -> 2.5 | C27: =1.875/2 -> 0.9375 | D27: =+C27*B27 -> 2.34375 | E27: Pistache Decortiquée 1kG | F27: 34.29 | G27: 1 | H27: =+G27*F27 -> 34.29 | I27: Beurre 82% Motte 25kG | J27: =IFERROR(VLOOKUP(I27,'TARIFS 12 2025'!B4:J492,9,FALSE),"") -> 4.8 | K27: 4 | L27: =+K27*J27 -> 19.2 | M27: Eau | N27: =IFERROR(VLOOKUP(M27,'TARIFS 12 2025'!B4:J502,9,FALSE),"") -> 0.004 | O27: 10.75 | P27: =+O27*N27 -> 0.043
A28: Sucre cassonade 25kG (Pure Canne) | B28: =IFERROR(VLOOKUP(A28,'TARIFS 12 2025'!B4:J526,9,FALSE),"") -> 1.467 | C28: 1.5625 | D28: =+C28*B28 -> 2.2921875 | E28: Drops chocolat 44% 25kG | F28: =IFERROR(VLOOKUP(E28,'TARIFS 12 2025'!B27:J492,9,FALSE),"") -> 5.95 | G28: 1 | H28: =+G28*F28 -> 5.95 | I28: Sel fin 25kG | J28: =IFERROR(VLOOKUP(I28,'TARIFS 12 2025'!B5:J493,9,FALSE),"") -> 0.27 | K28: 0.1 | L28: =+K28*J28 -> 0.027 | M28: Œuf Frais | N28: =IFERROR(VLOOKUP(M28,'TARIFS 12 2025'!B5:J503,9,FALSE),"") -> 2.72 | O28: 12 | P28: =+O28*N28 -> 32.64
A29: Sucre Crist Semoule 25kG | B29: =IFERROR(VLOOKUP(A29,'TARIFS 12 2025'!B5:J527,9,FALSE),"") -> 0.86 | C29: 1.5625 | D29: =+C29*B29 -> 1.34375 | E29: Pistache Pâte 3kg | F29: =IFERROR(VLOOKUP(E29,'TARIFS 12 2025'!B28:J493,9,FALSE),"") -> 76.5 | G29: 0.4 | H29: =+G29*F29 -> 30.6 | I29: Sucre Crist Semoule 25kG | J29: =IFERROR(VLOOKUP(I29,'TARIFS 12 2025'!B6:J494,9,FALSE),"") -> 0.86 | K29: 1 | L29: =+K29*J29 -> 0.86 | M29: Levure Hirondelle 1895 Bande 2,5kG | N29: =IFERROR(VLOOKUP(M29,'TARIFS 12 2025'!B6:J504,9,FALSE),"") -> 3.45 | O29: 1.75 | P29: =+O29*N29 -> 6.0375
A30: Œuf Frais | B30: =IFERROR(VLOOKUP(A30,'TARIFS 12 2025'!B6:J528,9,FALSE),"") -> 2.72 | C30: 1.25 | D30: =+C30*B30 -> 3.4 | F30: =IFERROR(VLOOKUP(E30,'TARIFS 12 2025'!B29:J494,9,FALSE),"") | I30: Farine Emilie TF T65 | J30: =IFERROR(VLOOKUP(I30,'TARIFS 12 2025'!B7:J495,9,FALSE),"") -> 0.705 | K30: 4 | L30: =+K30*J30 -> 2.82 | M30: Sucre Crist Semoule 25kG | N30: =IFERROR(VLOOKUP(M30,'TARIFS 12 2025'!B7:J505,9,FALSE),"") -> 0.86 | O30: 6 | P30: =+O30*N30 -> 5.16
A31: Levure chimique 1kG | B31: =IFERROR(VLOOKUP(A31,'TARIFS 12 2025'!B7:J529,9,FALSE),"") -> 4.69 | C31: 0.0625 | D31: =+C31*B31 -> 0.293125 | F31: =IFERROR(VLOOKUP(E31,'TARIFS 12 2025'!B30:J495,9,FALSE),"") | I31: Œuf Frais | J31: =IFERROR(VLOOKUP(I31,'TARIFS 12 2025'!B8:J496,9,FALSE),"") -> 2.72 | K31: 4.7 | L31: =+K31*J31 -> 12.784 | M31: Sel fin 25kG | N31: =IFERROR(VLOOKUP(M31,'TARIFS 12 2025'!B8:J506,9,FALSE),"") -> 0.27 | O31: 1 | P31: =+O31*N31 -> 0.27
A32: Sel fin 25kG | B32: =IFERROR(VLOOKUP(A32,'TARIFS 12 2025'!B8:J530,9,FALSE),"") -> 0.27 | C32: 0.0625 | D32: =+C32*B32 -> 0.016875 | F32: =IFERROR(VLOOKUP(E32,'TARIFS 12 2025'!B31:J496,9,FALSE),"") | I32: Sucre Grain n°6 10kG | J32: =IFERROR(VLOOKUP(I32,'TARIFS 12 2025'!B3:J476,9,FALSE),"") -> 1.776 | K32: 3 | L32: =+K32*J32 -> 5.328 | M32: Top Fournil | N32: =IFERROR(VLOOKUP(M32,'TARIFS 12 2025'!B9:J507,9,FALSE),"") -> 4.49 | O32: 0.25 | P32: =+O32*N32 -> 1.1225
A33: Farine T45 | B33: =IFERROR(VLOOKUP(A33,'TARIFS 12 2025'!B9:J531,9,FALSE),"") -> 1.05 | C33: 4.375 | D33: =+C33*B33 -> 4.59375 | F33: =IFERROR(VLOOKUP(E33,'TARIFS 12 2025'!B32:J497,9,FALSE),"") | I33: Agent Démoulage Aerosol 500mL | J33: =IFERROR(VLOOKUP(I33,'TARIFS 12 2025'!B3:J508,9,FALSE),"") -> 2.75 | K33: 1 | L33: =+K33*J33 -> 2.75 | M33: Margarine 10kg | N33: =IFERROR(VLOOKUP(M33,'TARIFS 12 2025'!B10:J508,9,FALSE),"") -> 2.5 | O33: 15 | P33: =+O33*N33 -> 37.5
A34: Drops chocolat 44% 25kG | B34: =IFERROR(VLOOKUP(A34,'TARIFS 12 2025'!B10:J532,9,FALSE),"") -> 5.95 | C34: 3.125 | D34: =+C34*B34 -> 18.59375 | J34: =IFERROR(VLOOKUP(I34,'TARIFS 12 2025'!B11:J499,9,FALSE),"") | M34: Rhum 40° 20L + taxe | N34: =IFERROR(VLOOKUP(M34,'TARIFS 12 2025'!B11:J509,9,FALSE),"") -> 2.42 | O34: 2.5 | P34: =+O34*N34 -> 6.05
B35: =IFERROR(VLOOKUP(A35,'TARIFS 12 2025'!B12:J534,9,FALSE),"") | J35: =IFERROR(VLOOKUP(I35,'TARIFS 12 2025'!B12:J500,9,FALSE),"")
F36: =IFERROR(VLOOKUP(E36,'TARIFS 12 2025'!B35:J500,9,FALSE),"") | J36: =IFERROR(VLOOKUP(I36,'TARIFS 12 2025'!F13:N503,9,FALSE),"") | N36: =IFERROR(VLOOKUP(M36,'TARIFS 12 2025'!J13:R503,9,FALSE),"")
F37: =IFERROR(VLOOKUP(E37,'TARIFS 12 2025'!B36:J501,9,FALSE),"") | J37: =IFERROR(VLOOKUP(I37,'TARIFS 12 2025'!F14:N504,9,FALSE),"") | N37: =IFERROR(VLOOKUP(M37,'TARIFS 12 2025'!J14:R504,9,FALSE),"")
C39: pour 150 | D39: =+SUM(D26:D37) -> 37.377188 | G39: pour 120 | H39: =+SUM(H26:H37) -> 91.13375 | K39: pour 2100 | L39: =+SUM(L26:L37) -> 43.789 | O39: pour 111,75 | P39: =+SUM(P26:P37) -> 124.073
C40: pour 1 | D40: =+D39/150 -> 0.24918125 | G40: pour 1 | H40: =+H39/120 -> 0.75944792 | K40: pour 1 | L40: =+L39/2100 -> 0.020851905 | O40: pour 1 | P40: =+P39/111.75 -> 1.1102729
C42: Vendu HT | D42: =2*0.945 -> 1.89 | G42: Vendu HT | H42: =3.8*0.945 -> 3.591 | K42: Vendu HT | L42: 0.21 | N42: 25 € TTC vente | O42: Vendu HT | P42: =25*0.945 -> 23.625
...

Sheet PAIN - PAP PARIS
A1: Coeff souhaité | B1: 8
A2: PAIN COMPLET | E2: TRADITION | I2: TRADIGRAINE
B3: Prix au kilo | C3: Quantité | F3: Prix au kilo | G3: Quantité | J3: Prix au kilo | K3: Quantité | N3: Prix au kilo | O3: Quantité
A4: Farine Complet Arthur | B4: =IFERROR(VLOOKUP(A4,'TARIFS 12 2025'!B3:J461,9,FALSE),"") -> 0.995 | C4: 1 | D4: =+C4*B4 -> 0.995 | E4: Farine Emilie TF T65 | F4: =IFERROR(VLOOKUP(E4,'TARIFS 12 2025'!B3:J466,9,FALSE),"") -> 0.705 | G4: 1 | H4: =+G4*F4 -> 0.705 | I4: Farine Emilie TF T65 | J4: =IFERROR(VLOOKUP(I4,'TARIFS 12 2025'!B3:J502,9,FALSE),"") -> 0.705 | K4: 1 | L4: =+K4*J4 -> 0.705 | N4: =IFERROR(VLOOKUP(M4,'TARIFS 12 2025'!B3:J510,9,FALSE),"") | P4: =+O4*N4 -> #VALUE!
A5: Eau | B5: =IFERROR(VLOOKUP(A5,'TARIFS 12 2025'!B4:J461,9,FALSE),"") -> 0.004 | C5: 0.7 | D5: =+C5*B5 -> 0.0028 | E5: Eau | F5: =IFERROR(VLOOKUP(E5,'TARIFS 12 2025'!B4:J469,9,FALSE),"") -> 0.004 | G5: 0.73 | H5: =+G5*F5 -> 0.00292 | I5: Eau | J5: =IFERROR(VLOOKUP(I5,'TARIFS 12 2025'!B4:J503,9,FALSE),"") -> 0.004 | K5: 0.73 | L5: =+K5*J5 -> 0.00292 | N5: =IFERROR(VLOOKUP(M5,'TARIFS 12 2025'!B4:J511,9,FALSE),"") | P5: =+O5*N5 -> #VALUE!
A6: Sel fin 25kG | B6: =IFERROR(VLOOKUP(A6,'TARIFS 12 2025'!B5:J462,9,FALSE),"") -> 0.27 | C6: 0.022 | D6: =+C6*B6 -> 0.00594 | E6: Sel fin 25kG | F6: =IFERROR(VLOOKUP(E6,'TARIFS 12 2025'!B5:J470,9,FALSE),"") -> 0.27 | G6: 0.022 | H6: =+G6*F6 -> 0.00594 | I6: Sel fin 25kG | J6: =IFERROR(VLOOKUP(I6,'TARIFS 12 2025'!B5:J504,9,FALSE),"") -> 0.27 | K6: 0.022 | L6: =+K6*J6 -> 0.00594 | N6: =IFERROR(VLOOKUP(M6,'TARIFS 12 2025'!B5:J512,9,FALSE),"") | P6: =+O6*N6 -> #VALUE!
A7: Levure Hirondelle 1895 Bande 2,5kG | B7: =IFERROR(VLOOKUP(A7,'TARIFS 12 2025'!B6:J463,9,FALSE),"") -> 3.45 | C7: 0.005 | D7: =+C7*B7 -> 0.01725 | E7: Levure Hirondelle 1895 Bande 2,5kG | F7: =IFERROR(VLOOKUP(E7,'TARIFS 12 2025'!B6:J471,9,FALSE),"") -> 3.45 | G7: 0.006 | H7: =+G7*F7 -> 0.0207 | I7: Levure Hirondelle 1895 Bande 2,5kG | J7: =IFERROR(VLOOKUP(I7,'TARIFS 12 2025'!B6:J505,9,FALSE),"") -> 3.45 | K7: 0.006 | L7: =+K7*J7 -> 0.0207 | N7: =IFERROR(VLOOKUP(M7,'TARIFS 12 2025'!B6:J513,9,FALSE),"") | P7: =+O7*N7 -> #VALUE!
A8: Levain Dur | B8: =IFERROR(VLOOKUP(A8,'TARIFS 12 2025'!B7:J463,9,FALSE),"") -> 0.71633333 | C8: 0.1 | D8: =+C8*B8 -> 0.071633333 | E8: Levain Dur | F8: =IFERROR(VLOOKUP(E8,'TARIFS 12 2025'!B7:J472,9,FALSE),"") -> 0.71633333 | G8: 0.1 | H8: =+G8*F8 -> 0.071633333 | I8: Levain Dur | J8: =IFERROR(VLOOKUP(I8,'TARIFS 12 2025'!B7:J506,9,FALSE),"") -> 0.71633333 | K8: 0.1 | L8: =+K8*J8 -> 0.071633333 | N8: =IFERROR(VLOOKUP(M8,'TARIFS 12 2025'!B7:J514,9,FALSE),"") | P8: =+O8*N8 -> #VALUE!
B9: =IFERROR(VLOOKUP(A9,'TARIFS 12 2025'!B8:J464,9,FALSE),"") | F9: =IFERROR(VLOOKUP(E9,'TARIFS 12 2025'!B8:J473,9,FALSE),"") | I9: Mélange 6 Graines 25kG | J9: =IFERROR(VLOOKUP(I9,'TARIFS 12 2025'!B8:J507,9,FALSE),"") -> 2.11 | K9: 0.1 | L9: =+K9*J9 -> 0.211 | N9: =IFERROR(VLOOKUP(M9,'TARIFS 12 2025'!B8:J515,9,FALSE),"") | P9: =+O9*N9 -> #VALUE!
B10: =IFERROR(VLOOKUP(A10,'TARIFS 12 2025'!B9:J465,9,FALSE),"") | F10: =IFERROR(VLOOKUP(E10,'TARIFS 12 2025'!B9:J474,9,FALSE),"") | I10: Eau | J10: =IFERROR(VLOOKUP(I10,'TARIFS 12 2025'!B9:J508,9,FALSE),"") -> 0.004 | K10: 0.1 | L10: =+K10*J10 -> 0.0004 | N10: =IFERROR(VLOOKUP(M10,'TARIFS 12 2025'!B9:J516,9,FALSE),"")
B11: =IFERROR(VLOOKUP(A11,'TARIFS 12 2025'!B10:J466,9,FALSE),"") | J11: =IFERROR(VLOOKUP(I11,'TARIFS 12 2025'!B10:J509,9,FALSE),"") | N11: =IFERROR(VLOOKUP(M11,'TARIFS 12 2025'!B10:J517,9,FALSE),"")
B12: =IFERROR(VLOOKUP(A12,'TARIFS 12 2025'!B11:J469,9,FALSE),"") | J12: =IFERROR(VLOOKUP(I12,'TARIFS 12 2025'!B11:J510,9,FALSE),"") | N12: =IFERROR(VLOOKUP(M12,'TARIFS 12 2025'!B11:J518,9,FALSE),"")
B13: =IFERROR(VLOOKUP(A13,'TARIFS 12 2025'!B12:J470,9,FALSE),"") | J13: =IFERROR(VLOOKUP(I13,'TARIFS 12 2025'!B12:J511,9,FALSE),"") | N13: =IFERROR(VLOOKUP(M13,'TARIFS 12 2025'!B12:J519,9,FALSE),"")
B14: =IFERROR(VLOOKUP(A14,'TARIFS 12 2025'!B13:J471,9,FALSE),"") | J14: =IFERROR(VLOOKUP(I14,'TARIFS 12 2025'!B13:J512,9,FALSE),"") | N14: =IFERROR(VLOOKUP(M14,'TARIFS 12 2025'!B13:J520,9,FALSE),"")
J15: =IFERROR(VLOOKUP(I15,'TARIFS 12 2025'!B14:J513,9,FALSE),"") | N15: =IFERROR(VLOOKUP(M15,'TARIFS 12 2025'!B14:J521,9,FALSE),"")
C17: pour 5,3 | D17: =+SUM(D4:D15) -> 1.0926233 | G17: pour 7,15 | H17: =+SUM(H4:H15) -> 0.80619333 | K17: pour 7,22 | L17: =+SUM(L4:L15) -> 1.0175933 | O17: pour 4,73 | P17: =+SUM(P4:P15) -> #VALUE!
C18: pour 1 | D18: =+D17/5.3 -> 0.20615535 | G18: pour 1 | H18: =+H17/7.15 -> 0.11275431 | K18: pour 1 | L18: =+L17/7.22 -> 0.1409409 | O18: pour 1 | P18: =+P17/4.73 -> #VALUE!
M19: 9445
C20: Vendu HT | D20: 2.74 | G20: Vendu HT | H20: 1.09 | K20: Vendu HT | L20: 1.323 | O20: Vendu HT | P20: 0.6615
C21: Coef | D21: =+D20/D18 -> 13.290948 | G21: Coef | H21: =+H20/H18 -> 9.667036 | K21: Coef | L21: =+L20/L18 -> 9.3869129 | O21: Coef | P21: =+P20/P18 -> #VALUE!
A24: COOKIE
B25: Prix au kilo | C25: Quantité | F25: Prix au kilo | G25: Quantité | J25: Prix au kilo | K25: Quantité | N25: Prix au kilo | O25: Quantité
B26: =IFERROR(VLOOKUP(A26,'TARIFS 12 2025'!B3:J525,9,FALSE),"") | D26: =+C26*B26 -> #VALUE! | F26: =IFERROR(VLOOKUP(E26,'TARIFS 12 2025'!B3:J493,9,FALSE),"") | H26: =+G26*F26 -> #VALUE! | J26: =IFERROR(VLOOKUP(I26,'TARIFS 12 2025'!B3:J491,9,FALSE),"") | L26: =+K26*J26 -> #VALUE! | N26: =IFERROR(VLOOKUP(M26,'TARIFS 12 2025'!B3:J501,9,FALSE),"") | P26: =+O26*N26 -> #VALUE!
B27: =IFERROR(VLOOKUP(A27,'TARIFS 12 2025'!B4:J526,9,FALSE),"") | D27: =+C27*B27 -> #VALUE! | F27: =IFERROR(VLOOKUP(E27,'TARIFS 12 2025'!B4:J494,9,FALSE),"") | H27: =+G27*F27 -> #VALUE! | J27: =IFERROR(VLOOKUP(I27,'TARIFS 12 2025'!B4:J492,9,FALSE),"") | L27: =+K27*J27 -> #VALUE! | N27: =IFERROR(VLOOKUP(M27,'TARIFS 12 2025'!B4:J502,9,FALSE),"") | P27: =+O27*N27 -> #VALUE!
B28: =IFERROR(VLOOKUP(A28,'TARIFS 12 2025'!B5:J527,9,FALSE),"") | D28: =+C28*B28 -> #VALUE! | F28: =IFERROR(VLOOKUP(E28,'TARIFS 12 2025'!B5:J495,9,FALSE),"") | H28: =+G28*F28 -> #VALUE! | J28: =IFERROR(VLOOKUP(I28,'TARIFS 12 2025'!B5:J493,9,FALSE),"") | L28: =+K28*J28 -> #VALUE! | N28: =IFERROR(VLOOKUP(M28,'TARIFS 12 2025'!B5:J503,9,FALSE),"") | P28: =+O28*N28 -> #VALUE!
B29: =IFERROR(VLOOKUP(A29,'TARIFS 12 2025'!B6:J528,9,FALSE),"") | D29: =+C29*B29 -> #VALUE! | F29: =IFERROR(VLOOKUP(E29,'TARIFS 12 2025'!B6:J496,9,FALSE),"") | H29: =+G29*F29 -> #VALUE! | J29: =IFERROR(VLOOKUP(I29,'TARIFS 12 2025'!B6:J494,9,FALSE),"") | L29: =+K29*J29 -> #VALUE! | N29: =IFERROR(VLOOKUP(M29,'TARIFS 12 2025'!B6:J504,9,FALSE),"") | P29: =+O29*N29 -> #VALUE!
B30: =IFERROR(VLOOKUP(A30,'TARIFS 12 2025'!B7:J529,9,FALSE),"") | D30: =+C30*B30 -> #VALUE! | F30: =IFERROR(VLOOKUP(E30,'TARIFS 12 2025'!B7:J497,9,FALSE),"") | H30: =+G30*F30 -> #VALUE! | J30: =IFERROR(VLOOKUP(I30,'TARIFS 12 2025'!B7:J495,9,FALSE),"") | L30: =+K30*J30 -> #VALUE! | N30: =IFERROR(VLOOKUP(M30,'TARIFS 12 2025'!B7:J505,9,FALSE),"") | P30: =+O30*N30 -> #VALUE!
B31: =IFERROR(VLOOKUP(A31,'TARIFS 12 2025'!B8:J530,9,FALSE),"") | D31: =+C31*B31 -> #VALUE! | F31: =IFERROR(VLOOKUP(E31,'TARIFS 12 2025'!B8:J498,9,FALSE),"") | H31: =+G31*F31 -> #VALUE! | J31: =IFERROR(VLOOKUP(I31,'TARIFS 12 2025'!B8:J496,9,FALSE),"") | L31: =+K31*J31 -> #VALUE! | N31: =IFERROR(VLOOKUP(M31,'TARIFS 12 2025'!B8:J506,9,FALSE),"") | P31: =+O31*N31 -> #VALUE!
B32: =IFERROR(VLOOKUP(A32,'TARIFS 12 2025'!B9:J531,9,FALSE),"") | D32: =+C32*B32 -> #VALUE! | F32: =IFERROR(VLOOKUP(E32,'TARIFS 12 2025'!B9:J499,9,FALSE),"") | H32: =+G32*F32 -> #VALUE! | J32: =IFERROR(VLOOKUP(I32,'TARIFS 12 2025'!B9:J497,9,FALSE),"") | L32: =+K32*J32 -> #VALUE! | N32: =IFERROR(VLOOKUP(M32,'TARIFS 12 2025'!B9:J507,9,FALSE),"") | P32: =+O32*N32 -> #VALUE!
B33: =IFERROR(VLOOKUP(A33,'TARIFS 12 2025'!B10:J532,9,FALSE),"") | F33: =IFERROR(VLOOKUP(E33,'TARIFS 12 2025'!B10:J500,9,FALSE),"") | H33: =+G33*F33 -> #VALUE! | J33: =IFERROR(VLOOKUP(I33,'TARIFS 12 2025'!B10:J498,9,FALSE),"") | L33: =+K33*J33 -> #VALUE! | N33: =IFERROR(VLOOKUP(M33,'TARIFS 12 2025'!B10:J508,9,FALSE),"") | P33: =+O33*N33 -> #VALUE!
B34: =IFERROR(VLOOKUP(A34,'TARIFS 12 2025'!B11:J533,9,FALSE),"") | F34: =IFERROR(VLOOKUP(E34,'TARIFS 12 2025'!B11:J501,9,FALSE),"") | H34: =+G34*F34 -> #VALUE! | J34: =IFERROR(VLOOKUP(I34,'TARIFS 12 2025'!B11:J499,9,FALSE),"") | L34: =+K34*J34 -> #VALUE! | N34: =IFERROR(VLOOKUP(M34,'TARIFS 12 2025'!B11:J509,9,FALSE),"") | P34: =+O34*N34 -> #VALUE!
B35: =IFERROR(VLOOKUP(A35,'TARIFS 12 2025'!B12:J534,9,FALSE),"") | J35: =IFERROR(VLOOKUP(I35,'TARIFS 12 2025'!B12:J500,9,FALSE),"") | L35: =+K35*J35 -> #VALUE!
F36: =IFERROR(VLOOKUP(E36,'TARIFS 12 2025'!B13:J503,9,FALSE),"") | J36: =IFERROR(VLOOKUP(I36,'TARIFS 12 2025'!F13:N503,9,FALSE),"") | N36: =IFERROR(VLOOKUP(M36,'TARIFS 12 2025'!J13:R503,9,FALSE),"")
F37: =IFERROR(VLOOKUP(E37,'TARIFS 12 2025'!B14:J504,9,FALSE),"") | J37: =IFERROR(VLOOKUP(I37,'TARIFS 12 2025'!F14:N504,9,FALSE),"") | N37: =IFERROR(VLOOKUP(M37,'TARIFS 12 2025'!J14:R504,9,FALSE),"")
C39: pour 25 | D39: =+SUM(D26:D37) -> #VALUE! | G39: pour 44,72 | H39: =+SUM(H26:H37) -> #VALUE! | K39: pour 56 | L39: =+SUM(L26:L37) -> #VALUE! | O39: pour 112 | P39: =+SUM(P26:P37) -> #VALUE!
C40: pour 1 | D40: =+D39/25 -> #VALUE! | G40: pour 1 | H40: =+H39/44.72 -> #VALUE! | K40: pour 1 | L40: =+L39/56 -> #VALUE! | O40: pour 1 | P40: =+P39/112 -> #VALUE!
A41: 10750
C42: Vendu HT | D42: 1.7955 | G42: Vendu HT | H42: 1.75 | K42: Vendu HT | L42: 0.99 | O42: Vendu HT | P42: 0.9
C43: Coef | D43: =+D42/D40 -> #VALUE! | G43: Coef | H43: =+H42/H40 -> #VALUE! | K43: Coef | L43: =+L42/L40 -> #VALUE! | O43: Coef | P43: =+P42/P40 -> #VALUE!

Sheet PATISSERIE - PAP PARIS
A1: Coeff souhaité | B1: 4
A2: FLAN | E2: TARTELETTE Abricot | I2: Falette Grangipane | M2: TARTELETTE POMME
B3: Prix au kilo | C3: Quantité | F3: Prix au kilo | G3: Quantité | J3: Prix au kilo | K3: Quantité | N3: Prix au kilo | O3: Quantité
A4: Feuilletage | B4: =IFERROR(VLOOKUP(A4,'TARIFS 12 2025'!B3:J461,9,FALSE),"") -> 1.69113 | C4: 0.4 | D4: =+C4*B4 -> 0.67645201 | E4: Sablée Breton | F4: =IFERROR(VLOOKUP(E4,'TARIFS 12 2025'!B3:J466,9,FALSE),"") -> 2.429856 | G4: 0.048 | H4: =+G4*F4 -> 0.11663309 | I4: Feuilletage | J4: =IFERROR(VLOOKUP(I4,'TARIFS 12 2025'!B3:J502,9,FALSE),"") -> 1.69113 | K4: 0.38 | L4: =+K4*J4 -> 0.64262941 | M4: Feuilletage | N4: =IFERROR(VLOOKUP(M4,'TARIFS 12 2025'!B3:J510,9,FALSE),"") -> 1.69113 | O4: 0.05 | P4: =+O4*N4 -> 0.084556501
A5: Crème Patissière | B5: =IFERROR(VLOOKUP(A5,'TARIFS 12 2025'!B4:J461,9,FALSE),"") -> 0.9775 | C5: 1.2 | D5: =+C5*B5 -> 1.173 | E5: Ganache montée | F5: =IFERROR(VLOOKUP(E5,'TARIFS 12 2025'!B4:J469,9,FALSE),"") -> 6.5775299 | G5: 0.015 | H5: =+G5*F5 -> 0.098662948 | I5: Crème Patissière | J5: =IFERROR(VLOOKUP(I5,'TARIFS 12 2025'!B4:J503,9,FALSE),"") -> 0.9775 | K5: =0.22/3 -> 0.073333333 | L5: =+K5*J5 -> 0.071683333 | M5: Compote 33% 5/1 UNL | N5: =IFERROR(VLOOKUP(M5,'TARIFS 12 2025'!B4:J511,9,FALSE),"") -> 7.7 | O5: 0.02 | P5: =2.31/3*0.05 -> 0.0385
A6: Caissette Ronde 1201F70 | B6: =IFERROR(VLOOKUP(A6,'TARIFS 12 2025'!B5:J462,9,FALSE),"") -> 0.006878 | C6: 8 | D6: =+C6*B6 -> 0.055024 | E6: Abricot 1/2 pelé sirop 5/1 | F6: =9.88/2.4 -> 4.1166667 | G6: 0.06 | H6: =+G6*F6 -> 0.247 | I6: Amande poudre blanche 10kg | J6: =IFERROR(VLOOKUP(I6,'TARIFS 12 2025'!B5:J504,9,FALSE),"") -> 5.24 | K6: =0.22/3*2*0.25 -> 0.036666667 | L6: =+K6*J6 -> 0.19213333 | M6: Pomme gala 18,2kG | N6: =IFERROR(VLOOKUP(M6,'TARIFS 12 2025'!B5:J512,9,FALSE),"") -> 1.03 | O6: 0.09 | P6: =+O6*N6 -> 0.0927
F7: =IFERROR(VLOOKUP(E7,'TARIFS 12 2025'!B6:J471,9,FALSE),"") | I7: Œuf Frais | J7: =IFERROR(VLOOKUP(I7,'TARIFS 12 2025'!B6:J505,9,FALSE),"") -> 2.72 | K7: =0.22/3*2*0.25 -> 0.036666667 | L7: =+K7*J7 -> 0.099733333 | N7: =IFERROR(VLOOKUP(M7,'TARIFS 12 2025'!B6:J513,9,FALSE),"")
B8: =IFERROR(VLOOKUP(A8,'TARIFS 12 2025'!B7:J463,9,FALSE),"") | F8: =IFERROR(VLOOKUP(E8,'TARIFS 12 2025'!B7:J472,9,FALSE),"") | I8: Beurre 82% Motte 25kG | J8: =IFERROR(VLOOKUP(I8,'TARIFS 12 2025'!B7:J506,9,FALSE),"") -> 4.8 | K8: =0.22/3*2*0.25 -> 0.036666667 | L8: =+K8*J8 -> 0.176 | N8: =IFERROR(VLOOKUP(M8,'TARIFS 12 2025'!B7:J514,9,FALSE),"")
B9: =IFERROR(VLOOKUP(A9,'TARIFS 12 2025'!B8:J464,9,FALSE),"") | F9: =IFERROR(VLOOKUP(E9,'TARIFS 12 2025'!B8:J473,9,FALSE),"") | I9: Sucre Crist Semoule 25kG | J9: =IFERROR(VLOOKUP(I9,'TARIFS 12 2025'!B8:J507,9,FALSE),"") -> 0.86 | K9: =0.22/3*2*0.25 -> 0.036666667 | L9: =+K9*J9 -> 0.031533333 | N9: =IFERROR(VLOOKUP(M9,'TARIFS 12 2025'!B8:J515,9,FALSE),"")
B10: =IFERROR(VLOOKUP(A10,'TARIFS 12 2025'!B9:J465,9,FALSE),"") | F10: =IFERROR(VLOOKUP(E10,'TARIFS 12 2025'!B9:J474,9,FALSE),"") | I10: Plaque ronds uni Noir et Or 22 | J10: =IFERROR(VLOOKUP(I10,'TARIFS 12 2025'!B9:J508,9,FALSE),"") -> 8.85 | K10: 0.01 | L10: =+K10*J10 -> 0.0885 | N10: =IFERROR(VLOOKUP(M10,'TARIFS 12 2025'!B9:J516,9,FALSE),"")
B11: =IFERROR(VLOOKUP(A11,'TARIFS 12 2025'!B10:J466,9,FALSE),"") | I11: Fèves 2024 | J11: 0.6 | K11: 1 | L11: =+K11*J11 -> 0.6 | N11: =IFERROR(VLOOKUP(M11,'TARIFS 12 2025'!B10:J517,9,FALSE),"")
B12: =IFERROR(VLOOKUP(A12,'TARIFS 12 2025'!B11:J469,9,FALSE),"") | I12: Couronne | J12: =IFERROR(VLOOKUP(I12,'TARIFS 12 2025'!B11:J510,9,FALSE),"") -> 4.62 | K12: 0.01 | L12: =+K12*J12 -> 0.0462 | N12: =IFERROR(VLOOKUP(M12,'TARIFS 12 2025'!B11:J518,9,FALSE),"")
B13: =IFERROR(VLOOKUP(A13,'TARIFS 12 2025'!B12:J470,9,FALSE),"") | I13: Sac à galette | J13: =IFERROR(VLOOKUP(I13,'TARIFS 12 2025'!B12:J511,9,FALSE),"") -> 11.05 | K13: 0.01 | L13: =+K13*J13 -> 0.1105 | N13: =IFERROR(VLOOKUP(M13,'TARIFS 12 2025'!B12:J519,9,FALSE),"")
B14: =IFERROR(VLOOKUP(A14,'TARIFS 12 2025'!B13:J471,9,FALSE),"") | J14: =IFERROR(VLOOKUP(I14,'TARIFS 12 2025'!B13:J512,9,FALSE),"") | N14: =IFERROR(VLOOKUP(M14,'TARIFS 12 2025'!B13:J520,9,FALSE),"")
J15: =IFERROR(VLOOKUP(I15,'TARIFS 12 2025'!B14:J513,9,FALSE),"") | N15: =IFERROR(VLOOKUP(M15,'TARIFS 12 2025'!B14:J521,9,FALSE),"")
C17: pour 8 | D17: =+SUM(D4:D15) -> 1.904476 | G17: pour 7,15 | H17: =+SUM(H4:H15) -> 0.46229604 | K17: pour 1 | L17: =+SUM(L4:L15) -> 2.0589127 | O17: pour 1 | P17: =+SUM(P4:P15) -> 0.2157565
C18: pour 1 | D18: =+D17/8 -> 0.2380595 | G18: pour 1 | H18: =+H17 -> 0.46229604 | K18: pour 1 | L18: =+L17 -> 2.0589127 | O18: pour 1 | P18: =+P17 -> 0.2157565
D19: 2.05 | G19: Vendu TTC | H19: 2.8 | K19: Vendu TTC | L19: 17 | M19: 9445 | O19: Vendu TTC | P19: 2.8
C20: Vendu HT | D20: =D19/(1+5.5/100) -> 1.943128 | G20: Vendu HT | H20: =H19/(1+5.5/100) -> 2.6540284 | K20: Vendu HT | L20: =L19/(1+5.5/100) -> 16.113744 | O20: Vendu HT | P20: =P19/(1+5.5/100) -> 2.6540284
C21: Coef | D21: =+D20/D18 -> 8.1623626 | G21: Coef | H21: =+H20/H18 -> 5.7409716 | K21: Coef | L21: =L20/L18 -> 7.8263366 | O21: Coef | P21: =+P20/P18 -> 12.301036
G22: Marge | H22: =(H20-H18)*100/H20 -> 82.581346 | K22: Marge | L22: =(L20-L18)*100/L20 -> 87.22263 | O22: Marge | P22: =(P20-P18)*100/P20 -> 91.870603
A24: Tartelette Citron meringué | E24: Tartelette chocolat caramel | I24: Mangue passion | M24: Rocher coco
B25: Prix au kilo | C25: Quantité | F25: Prix au kilo | G25: Quantité | J25: Prix au kilo | K25: Quantité | N25: Prix au kilo | O25: Quantité
A26: Sablée Breton | B26: =IFERROR(VLOOKUP(A26,'TARIFS 12 2025'!B3:J525,9,FALSE),"") -> 2.429856 | C26: =0.045*60 -> 2.7 | D26: =+C26*B26 -> 6.5606113 | E26: Sablée Breton | F26: =IFERROR(VLOOKUP(E26,'TARIFS 12 2025'!B25:J492,9,FALSE),"") -> 2.429856 | G26: =0.035*60 -> 2.1 | H26: =+G26*F26 -> 5.1026976 | I26: Sablée Breton | J26: =IFERROR(VLOOKUP(I26,'TARIFS 12 2025'!B3:J491,9,FALSE),"") -> 2.429856 | K26: =0.045*65 -> 2.925 | L26: =+K26*J26 -> 7.1073289 | M26: Blanc Œuf Liquide 1kG | N26: =IFERROR(VLOOKUP(M26,'TARIFS 12 2025'!B3:J501,9,FALSE),"") -> 3.29 | O26: 0.8 | P26: =+O26*N26 -> 2.632
A27: Jaune Œuf Cocotine PEP 1kG | B27: =IFERROR(VLOOKUP(A27,'TARIFS 12 2025'!B4:J526,9,FALSE),"") -> 5.389 | C27: 1 | D27: =+C27*B27 -> 5.389 | E27: Crème UHT Bleue 35% | F27: =IFERROR(VLOOKUP(E27,'TARIFS 12 2025'!B26:J493,9,FALSE),"") -> 3.48 | G27: 1.05 | H27: =+G27*F27 -> 3.654 | I27: Jaune Œuf Cocotine PEP 1kG | J27: =IFERROR(VLOOKUP(I27,'TARIFS 12 2025'!B4:J492,9,FALSE),"") -> 5.389 | K27: 1 | L27: =+K27*J27 -> 5.389 | M27: Sucre Crist Semoule 25kG | N27: =IFERROR(VLOOKUP(M27,'TARIFS 12 2025'!B4:J502,9,FALSE),"") -> 0.86 | O27: 1 | P27: =+O27*N27 -> 0.86
A28: Œuf Frais | B28: =IFERROR(VLOOKUP(A28,'TARIFS 12 2025'!B5:J527,9,FALSE),"") -> 2.72 | C28: 0.33 | D28: =+C28*B28 -> 0.8976 | E28: Couv noir 67% 10kG | F28: =IFERROR(VLOOKUP(E28,'TARIFS 12 2025'!B27:J494,9,FALSE),"") -> 12.78 | G28: 1.5 | H28: =+G28*F28 -> 19.17 | I28: Œuf Frais | J28: =IFERROR(VLOOKUP(I28,'TARIFS 12 2025'!B5:J493,9,FALSE),"") -> 2.72 | K28: 0.33 | L28: =+K28*J28 -> 0.8976 | N28: =IFERROR(VLOOKUP(M28,'TARIFS 12 2025'!B5:J503,9,FALSE),"") | O28: 1.25 | P28: =+O28*N28 -> #VALUE!
A29: Citron presse 10 litres | B29: =IFERROR(VLOOKUP(A29,'TARIFS 12 2025'!B6:J528,9,FALSE),"") -> 2.66 | C29: 2 | D29: =+C29*B29 -> 5.32 | E29: Glucose sirop eau 15kG | F29: =IFERROR(VLOOKUP(E29,'TARIFS 12 2025'!B28:J495,9,FALSE),"") -> 1.464 | G29: 0.135 | H29: =+G29*F29 -> 0.19764 | I29: Citron presse 10 litres | J29: =IFERROR(VLOOKUP(I29,'TARIFS 12 2025'!B6:J494,9,FALSE),"") -> 2.66 | K29: 2 | L29: =+K29*J29 -> 5.32 | N29: =IFERROR(VLOOKUP(M29,'TARIFS 12 2025'!B6:J504,9,FALSE),"") | P29: =+O29*N29 -> #VALUE!
A30: Poudre Crème chaud 25kg | B30: =IFERROR(VLOOKUP(A30,'TARIFS 12 2025'!B7:J529,9,FALSE),"") -> 2.5 | C30: 0.2 | D30: =+C30*B30 -> 0.5 | E30: Beurre 82% Motte 25kG | F30: =IFERROR(VLOOKUP(E30,'TARIFS 12 2025'!B29:J496,9,FALSE),"") -> 4.8 | G30: 0.375 | H30: =+G30*F30 -> 1.8 | I30: Poudre Crème chaud 25kg | J30: =IFERROR(VLOOKUP(I30,'TARIFS 12 2025'!B7:J495,9,FALSE),"") -> 2.5 | K30: 0.2 | L30: =+K30*J30 -> 0.5 | N30: =IFERROR(VLOOKUP(M30,'TARIFS 12 2025'!B7:J505,9,FALSE),"") | P30: =+O30*N30 -> #VALUE!
A31: Beurre 82% Motte 25kG | B31: =IFERROR(VLOOKUP(A31,'TARIFS 12 2025'!B8:J530,9,FALSE),"") -> 4.8 | C31: 0.864 | D31: =+C31*B31 -> 4.1472 | E31: Sucre Crist Semoule 25kG | F31: =IFERROR(VLOOKUP(E31,'TARIFS 12 2025'!B8:J498,9,FALSE),"") -> 0.86 | G31: 0.6 | H31: =+G31*F31 -> 0.516 | I31: Beurre 82% Motte 25kG | J31: =IFERROR(VLOOKUP(I31,'TARIFS 12 2025'!B8:J496,9,FALSE),"") -> 4.8 | K31: 0.864 | L31: =+K31*J31 -> 4.1472 | N31: =IFERROR(VLOOKUP(M31,'TARIFS 12 2025'!B8:J506,9,FALSE),"") | P31: =+O31*N31 -> #VALUE!
A32: Sucre Crist Semoule 25kG | B32: =IFERROR(VLOOKUP(A32,'TARIFS 12 2025'!B9:J531,9,FALSE),"") -> 0.86 | C32: =1.332+0.5 -> 1.832 | D32: =+C32*B32 -> 1.57552 | F32: =IFERROR(VLOOKUP(E32,'TARIFS 12 2025'!B9:J499,9,FALSE),"") | I32: Sucre Crist Semoule 25kG | J32: =IFERROR(VLOOKUP(I32,'TARIFS 12 2025'!B9:J497,9,FALSE),"") -> 0.86 | K32: 0.1 | L32: =+K32*J32 -> 0.086 | N32: =IFERROR(VLOOKUP(M32,'TARIFS 12 2025'!B9:J507,9,FALSE),"") | P32: =+O32*N32 -> #VALUE!
A33: Blanc Œuf Liquide 1kG | B33: =IFERROR(VLOOKUP(A33,'TARIFS 12 2025'!B10:J532,9,FALSE),"") -> 3.29 | C33: 0.25 | D33: =+C33*B33 -> 0.8225 | F33: =IFERROR(VLOOKUP(E33,'TARIFS 12 2025'!B10:J500,9,FALSE),"") | I33: Purée Passion 10kg | J33: =IFERROR(VLOOKUP(I33,'TARIFS 12 2025'!B10:J498,9,FALSE),"") -> 9.17 | K33: 0.5 | L33: =+K33*J33 -> 4.585 | N33: =IFERROR(VLOOKUP(M33,'TARIFS 12 2025'!B10:J508,9,FALSE),"") | P33: =+O33*N33 -> #VALUE!
A34: Caissette Ronde 1201F70 | B34: =IFERROR(VLOOKUP(A34,'TARIFS 12 2025'!B33:J494,9,FALSE),"") -> 0.006878 | C34: 8 | D34: =+C34*B34 -> 0.055024 | F34: =IFERROR(VLOOKUP(E34,'TARIFS 12 2025'!B11:J501,9,FALSE),"") | I34: Caissette Ronde 1201F70 | J34: =IFERROR(VLOOKUP(I34,'TARIFS 12 2025'!B11:J499,9,FALSE),"") -> 0.006878 | K34: 8 | L34: =+K34*J34 -> 0.055024 | N34: =IFERROR(VLOOKUP(M34,'TARIFS 12 2025'!B11:J509,9,FALSE),"") | P34: =+O34*N34 -> #VALUE!
B35: =IFERROR(VLOOKUP(A35,'TARIFS 12 2025'!B12:J534,9,FALSE),"") | J35: =IFERROR(VLOOKUP(I35,'TARIFS 12 2025'!B12:J500,9,FALSE),"")
F36: =IFERROR(VLOOKUP(E36,'TARIFS 12 2025'!B13:J503,9,FALSE),"") | J36: =IFERROR(VLOOKUP(I36,'TARIFS 12 2025'!F13:N503,9,FALSE),"") | N36: =IFERROR(VLOOKUP(M36,'TARIFS 12 2025'!J13:R503,9,FALSE),"")
F37: =IFERROR(VLOOKUP(E37,'TARIFS 12 2025'!B14:J504,9,FALSE),"") | J37: =IFERROR(VLOOKUP(I37,'TARIFS 12 2025'!F14:N504,9,FALSE),"") | N37: =IFERROR(VLOOKUP(M37,'TARIFS 12 2025'!J14:R504,9,FALSE),"")
C39: Pour 60 | D39: =SUM(D26:D34) -> 25.267455 | G39: pour 60 | H39: =+SUM(H26:H37) -> 30.440338 | K39: pour 65 | L39: =+SUM(L26:L37) -> 28.087153 | O39: pour 112 | P39: =+SUM(P26:P37) -> #VALUE!
C40: pour 1 | D40: =+D39/60 -> 0.42112425 | G40: pour 1 | H40: =+H39/60 -> 0.50733896 | K40: pour 1 | L40: =+L39/65 -> 0.43211004 | O40: pour 1 | P40: =+P39/112 -> #VALUE!
C41: Vendu TTC | D41: 2.8 | G41: Vendu TTC | H41: 3.4 | K41: Vendu TTC | L41: 2.8 | O41: Vendu TTC | P41: 2.8
C42: Vendu HT | D42: =D41/(1+5.5/100) -> 2.6540284 | G42: Vendu HT | H42: =H41/(1+5.5/100) -> 3.2227488 | K42: Vendu HT | L42: =L41/(1+5.5/100) -> 2.6540284 | O42: Vendu HT | P42: =P41/(1+5.5/100) -> 2.6540284
C43: Coef | D43: =+D42/D40 -> 6.3022455 | G43: Coef | H43: =H42/H40 -> 6.3522597 | K43: Coef | L43: =+L42/L40 -> 6.1420198 | O43: Coef | P43: =+P42/P40 -> #VALUE!
...

Sheet TRAITEUR - PAP PARIS
A1: Coeff souhaité | B1: 4
A2: JAMBON BEURRE EMMENTAL | E2: COMPLET POULET | I2: COMPLET THON | M2: COMPLET JAMBON
B3: Prix au kilo | C3: Quantité | F3: Prix au kilo | G3: Quantité | J3: Prix au kilo | K3: Quantité | N3: Prix au kilo | O3: Quantité
A4: Pâte Tradition | B4: =IFERROR(VLOOKUP(A4,'TARIFS 12 2025'!B3:J487,9,FALSE),"") -> 0.11275431 | C4: 0.2 | D4: =+C4*B4 -> 0.022550862 | E4: Pâte Tradition | F4: =IFERROR(VLOOKUP(E4,'TARIFS 12 2025'!B3:J466,9,FALSE),"") -> 0.11275431 | G4: 0.2 | H4: =+G4*F4 -> 0.022550862 | I4: Pâte Tradition | J4: =IFERROR(VLOOKUP(I4,'TARIFS 12 2025'!B3:J502,9,FALSE),"") -> 0.11275431 | K4: 0.2 | L4: =+K4*J4 -> 0.022550862 | M4: Pâte Tradition | N4: =IFERROR(VLOOKUP(M4,'TARIFS 12 2025'!B3:J510,9,FALSE),"") -> 0.11275431 | O4: 0.25 | P4: =+O4*N4 -> 0.028188578
A5: Tartimalin Demi-sel 1kg | B5: =IFERROR(VLOOKUP(A5,'TARIFS 12 2025'!B4:J461,9,FALSE),"") | C5: 0.02 | D5: =+C5*B5 -> #VALUE! | E5: Mayonnaise 5L | F5: =IFERROR(VLOOKUP(E5,'TARIFS 12 2025'!B4:J469,9,FALSE),"")/5 -> 2.16 | G5: 0.07 | H5: =+G5*F5 -> 0.1512 | I5: Thon morceaux 650gr | J5: =IFERROR(VLOOKUP(I5,'TARIFS 12 2025'!B4:J503,9,FALSE),"") -> 3.88 | K5: 0.09 | L5: =+K5*J5 -> 0.3492 | M5: Mayonnaise 5L | N5: =IFERROR(VLOOKUP(M5,'TARIFS 12 2025'!B4:J511,9,FALSE),"")/5 -> 2.16 | O5: 0.07 | P5: =+O5*N5 -> 0.1512
A6: Jambon Blanc Tranche | B6: =IFERROR(VLOOKUP(A6,'TARIFS 12 2025'!B5:J462,9,FALSE),"")/20 -> 0.3495 | C6: 0.75 | D6: =+C6*B6 -> 0.262125 | E6: Salade batavia sachet | F6: =IFERROR(VLOOKUP(E6,'TARIFS 12 2025'!B5:J470,9,FALSE),"") -> 4.95 | G6: 0.01 | H6: =+G6*F6 -> 0.0495 | I6: Salade batavia sachet | J6: =IFERROR(VLOOKUP(I6,'TARIFS 12 2025'!B5:J504,9,FALSE),"") -> 4.95 | K6: 0.01 | L6: =+K6*J6 -> 0.0495 | M6: Salade batavia sachet | N6: =IFERROR(VLOOKUP(M6,'TARIFS 12 2025'!B5:J512,9,FALSE),"") -> 4.95 | O6: 0.001 | P6: =+O6*N6 -> 0.00495
A7: Emmental Tranchette 40 tranches kG | B7: =IFERROR(VLOOKUP(A7,'TARIFS 12 2025'!B6:J463,9,FALSE),"")/40 -> 0.00475 | C7: 1.5 | D7: =+C7*B7 -> 0.007125 | E7: Tomates rondes | F7: =IFERROR(VLOOKUP(E7,'TARIFS 12 2025'!B6:J471,9,FALSE),"") -> 2.25 | G7: 0.03 | H7: =+G7*F7 -> 0.0675 | I7: Tomates rondes | J7: =IFERROR(VLOOKUP(I7,'TARIFS 12 2025'!B6:J505,9,FALSE),"") -> 2.25 | K7: 0.03 | L7: =+K7*J7 -> 0.0675 | M7: Tomates rondes | N7: =IFERROR(VLOOKUP(M7,'TARIFS 12 2025'!B6:J513,9,FALSE),"") -> 2.25 | O7: 0.03 | P7: =+O7*N7 -> 0.0675
B8: =IFERROR(VLOOKUP(A8,'TARIFS 12 2025'!B7:J463,9,FALSE),"") | E8: Emincés poulet cuit Halal 2,5kg | F8: =IFERROR(VLOOKUP(E8,'TARIFS 12 2025'!B7:J472,9,FALSE),"") -> 7.4 | G8: 0.05 | H8: =+G8*F8 -> 0.37 | J8: =IFERROR(VLOOKUP(I8,'TARIFS 12 2025'!B7:J506,9,FALSE),"") | M8: Jambon Blanc Tranche | N8: =IFERROR(VLOOKUP(M8,'TARIFS 12 2025'!B7:J514,9,FALSE),"")/20 -> 0.3495 | O8: 1.5 | P8: =+O8*N8 -> 0.52425
B9: =IFERROR(VLOOKUP(A9,'TARIFS 12 2025'!B8:J464,9,FALSE),"") | F9: =IFERROR(VLOOKUP(E9,'TARIFS 12 2025'!B8:J473,9,FALSE),"") | J9: =IFERROR(VLOOKUP(I9,'TARIFS 12 2025'!B8:J507,9,FALSE),"") | N9: =IFERROR(VLOOKUP(M9,'TARIFS 12 2025'!B8:J515,9,FALSE),"")
B10: =IFERROR(VLOOKUP(A10,'TARIFS 12 2025'!B9:J465,9,FALSE),"") | F10: =IFERROR(VLOOKUP(E10,'TARIFS 12 2025'!B9:J474,9,FALSE),"") | J10: =IFERROR(VLOOKUP(I10,'TARIFS 12 2025'!B9:J508,9,FALSE),"") | N10: =IFERROR(VLOOKUP(M10,'TARIFS 12 2025'!B9:J516,9,FALSE),"")
B11: =IFERROR(VLOOKUP(A11,'TARIFS 12 2025'!B10:J466,9,FALSE),"") | J11: =IFERROR(VLOOKUP(I11,'TARIFS 12 2025'!B10:J509,9,FALSE),"") | N11: =IFERROR(VLOOKUP(M11,'TARIFS 12 2025'!B10:J517,9,FALSE),"")
B12: =IFERROR(VLOOKUP(A12,'TARIFS 12 2025'!B11:J469,9,FALSE),"") | J12: =IFERROR(VLOOKUP(I12,'TARIFS 12 2025'!B11:J510,9,FALSE),"") | N12: =IFERROR(VLOOKUP(M12,'TARIFS 12 2025'!B11:J518,9,FALSE),"")
B13: =IFERROR(VLOOKUP(A13,'TARIFS 12 2025'!B12:J470,9,FALSE),"") | J13: =IFERROR(VLOOKUP(I13,'TARIFS 12 2025'!B12:J511,9,FALSE),"") | N13: =IFERROR(VLOOKUP(M13,'TARIFS 12 2025'!B12:J519,9,FALSE),"")
B14: =IFERROR(VLOOKUP(A14,'TARIFS 12 2025'!B13:J471,9,FALSE),"") | J14: =IFERROR(VLOOKUP(I14,'TARIFS 12 2025'!B13:J512,9,FALSE),"") | N14: =IFERROR(VLOOKUP(M14,'TARIFS 12 2025'!B13:J520,9,FALSE),"")
J15: =IFERROR(VLOOKUP(I15,'TARIFS 12 2025'!B14:J513,9,FALSE),"") | N15: =IFERROR(VLOOKUP(M15,'TARIFS 12 2025'!B14:J521,9,FALSE),"")
C17: pour 1 | D17: =+SUM(D4:D15) -> #VALUE! | G17: pour 1 | H17: =+SUM(H4:H15) -> 0.66075086 | K17: pour 1 | L17: =+SUM(L4:L15) -> 0.48875086 | O17: pour 1 | P17: =+SUM(P4:P15) -> 0.77608858
C18: pour 1 | D18: =+D17 -> #VALUE! | G18: pour 1 | H18: =+H17 -> 0.66075086 | K18: pour 1 | L18: =+L17 -> 0.48875086 | O18: pour 1 | P18: =+P17 -> 0.77608858
C20: Vendu HT | D20: 4.25 | G20: Vendu HT | H20: 4.25 | K20: Vendu HT | L20: 4.25 | O20: Vendu HT | P20: 4.25
C21: Coef | D21: =+D20/D18 -> #VALUE! | G21: Coef | H21: =+H20/H18 -> 6.4320764 | K21: Coef | L21: =+L20/L18 -> 8.6956368 | O21: Coef | P21: =+P20/P18 -> 5.476179
